<mujoco model="G1_D">
  <compiler angle="radian" meshdir="meshes/"/>

  <statistic meansize="0.144785" extent="1.23314" center="0.025392 2.0634e-05 -0.245975"/>
  <default>
    <joint damping="0.001" armature="0.01" frictionloss="0.1"/>
  </default>
  <option timestep="0.002"/> 
  <option integrator="implicit"/>

  <asset>
    <mesh name="AGV_link" file="AGV_link.STL"/>
    <mesh name="Left_Wheel_Link" file="Left_Wheel_Link.STL"/>
    <mesh name="RIght_Wheel_Link" file="RIght_Wheel_Link.STL"/>
    <mesh name="LZ_ot_Link" file="LZ_ot_Link.STL"/>
    <mesh name="LZ_mt_Link" file="LZ_mt_Link.STL"/>
    <mesh name="LZ_it_Link" file="LZ_it_Link.STL"/>
    <mesh name="Pitching_Link" file="Pitching_Link.STL"/>
    <mesh name="Yaw_Link" file="Yaw_Link.STL"/>
    <mesh name="torso_link" file="torso_link.STL"/>
    <mesh name="logo_link" file="logo_link.STL"/>
    <mesh name="head_link" file="head_link.STL"/>
    <mesh name="left_shoulder_pitch_link" file="left_shoulder_pitch_link.STL"/>
    <mesh name="left_shoulder_roll_link" file="left_shoulder_roll_link.STL"/>
    <mesh name="left_shoulder_yaw_link" file="left_shoulder_yaw_link.STL"/>
    <mesh name="left_elbow_link" file="left_elbow_link.STL"/>
    <mesh name="left_wrist_roll_link" file="left_wrist_roll_link.STL"/>
    <mesh name="left_wrist_pitch_link" file="left_wrist_pitch_link.STL"/>
    <mesh name="left_wrist_yaw_link" file="left_wrist_yaw_link.STL"/>
    <mesh name="left_hand_palm_link" file="left_hand_palm_link.STL"/>
    <mesh name="left_hand_thumb_0_link" file="left_hand_thumb_0_link.STL"/>
    <mesh name="left_hand_thumb_1_link" file="left_hand_thumb_1_link.STL"/>
    <mesh name="left_hand_thumb_2_link" file="left_hand_thumb_2_link.STL"/>
    <mesh name="left_hand_middle_0_link" file="left_hand_middle_0_link.STL"/>
    <mesh name="left_hand_middle_1_link" file="left_hand_middle_1_link.STL"/>
    <mesh name="left_hand_index_0_link" file="left_hand_index_0_link.STL"/>
    <mesh name="left_hand_index_1_link" file="left_hand_index_1_link.STL"/>
    <mesh name="right_shoulder_pitch_link" file="right_shoulder_pitch_link.STL"/>
    <mesh name="right_shoulder_roll_link" file="right_shoulder_roll_link.STL"/>
    <mesh name="right_shoulder_yaw_link" file="right_shoulder_yaw_link.STL"/>
    <mesh name="right_elbow_link" file="right_elbow_link.STL"/>
    <mesh name="right_wrist_roll_link" file="right_wrist_roll_link.STL"/>
    <mesh name="right_wrist_pitch_link" file="right_wrist_pitch_link.STL"/>
    <mesh name="right_wrist_yaw_link" file="right_wrist_yaw_link.STL"/>
    <mesh name="right_hand_palm_link" file="right_hand_palm_link.STL"/>
    <mesh name="right_hand_thumb_0_link" file="right_hand_thumb_0_link.STL"/>
    <mesh name="right_hand_thumb_1_link" file="right_hand_thumb_1_link.STL"/>
    <mesh name="right_hand_thumb_2_link" file="right_hand_thumb_2_link.STL"/>
    <mesh name="right_hand_middle_0_link" file="right_hand_middle_0_link.STL"/>
    <mesh name="right_hand_middle_1_link" file="right_hand_middle_1_link.STL"/>
    <mesh name="right_hand_index_0_link" file="right_hand_index_0_link.STL"/>
    <mesh name="right_hand_index_1_link" file="right_hand_index_1_link.STL"/>
  </asset>

  <worldbody>
    <body name="AGV_link" pos="0.0 0.0 0.4">
      <inertial pos="4.31734e-05 -2.18029e-05 0.0431743" quat="0.99999 0.000234984 0.000398443 0.00445195" mass="40.3" diaginertia="1.00525 0.995147 0.172988"/>
      <joint name="floating_base_joint" type="free"/>
      <geom type="mesh" contype="0" conaffinity="0" group="1" density="0" rgba="0.792157 0.819608 0.933333 1" mesh="AGV_link"/>
      <geom type="mesh" rgba="0.792157 0.819608 0.933333 1" mesh="AGV_link"/>
      <geom pos="-0.00016264 0 0.5275" quat="1 0 0 0" type="mesh" contype="0" conaffinity="0" group="1" density="0" rgba="0.792157 0.819608 0.933333 1" mesh="LZ_ot_Link"/>
      <geom pos="-0.00016264 0 0.5275" quat="1 0 0 0" type="mesh" rgba="0.792157 0.819608 0.933333 1" mesh="LZ_ot_Link"/>
      <body name="Left_Wheel_Link" pos="0.00022503 0.2031 -0.0265">
        <inertial pos="-3e-06 -0.000309 -2e-06" quat="0.372939 0.600752 0.60077 0.372947" mass="1.5" diaginertia="0.00276373 0.00154174 0.00154164"/>
        <!-- <joint name="Left_Wheel_Joint" pos="0 0 0" axis="0 -1 0" range="-3.1416 3.1416" actuatorfrcrange="-8 8"/> -->
        <geom type="mesh" contype="0" conaffinity="0" group="1" density="0" rgba="0.792157 0.819608 0.933333 1" mesh="Left_Wheel_Link"/>
        <geom type="mesh" rgba="0.792157 0.819608 0.933333 1" mesh="Left_Wheel_Link"/>
        <body name="left_foot_end_link" pos="-0.01 0 -0.08">
          <geom type="sphere" size="0.01" contype="0" conaffinity="0" group="1" density="0" rgba="1 0 0 0"/>
        </body>
        <body name="left_toe_link" pos="0.01 0 -0.08">
          <geom type="sphere" size="0.01" contype="0" conaffinity="0" group="1" density="0" rgba="1 0 0 0"/>
        </body>
      </body>
      <body name="RIght_Wheel_Link" pos="0.00022503 -0.2031 -0.0265">
        <inertial pos="3e-06 0.000309 -2e-06" quat="0.516023 0.483432 0.483443 0.516039" mass="1.5" diaginertia="0.00276373 0.00154172 0.00154166"/>
        <!-- <joint name="Right_Wheel_Joint" pos="0 0 0" axis="0 1 0" range="-3.1416 3.1416" actuatorfrcrange="-8 8"/> -->
        <geom type="mesh" contype="0" conaffinity="0" group="1" density="0" rgba="0.792157 0.819608 0.933333 1" mesh="RIght_Wheel_Link"/>
        <geom type="mesh" rgba="0.792157 0.819608 0.933333 1" mesh="RIght_Wheel_Link"/>
        <body name="right_foot_end_link" pos="-0.01 0 -0.08">
          <geom type="sphere" size="0.01" contype="0" conaffinity="0" group="1" density="0" rgba="1 0 0 0"/>
        </body>
        <body name="right_toe_link" pos="0.01 0 -0.08">
          <geom type="sphere" size="0.01" contype="0" conaffinity="0" group="1" density="0" rgba="1 0 0 0"/>
        </body>
      </body>
      <body name="LZ_mt_Link" pos="0.00022503 0 0.5375">
        <inertial pos="0.000494 -6.2e-05 0.216016" quat="0.707107 0 0 0.707107" mass="3.3" diaginertia="0.0573529 0.0573527 0.0128473"/>
        <joint name="LZ_mt_Joint" pos="0 0 0" axis="0 0 1" type="slide" range="0 0.21" actuatorfrcrange="-500 500"/>
        <geom type="mesh" contype="0" conaffinity="0" group="1" density="0" rgba="0.792157 0.819608 0.933333 1" mesh="LZ_mt_Link"/>
        <body name="LZ_it_Link" pos="0.0013627 0.00020167 0.018">
          <inertial pos="0.0158757 -0.00132536 -0.107936" quat="0.736175 0.042947 0.0410595 0.674178" mass="5.289" diaginertia="0.15517 0.152893 0.0154348"/>
          <joint name="LZ_it_Joint" pos="0 0 0" axis="0 0 1" type="slide" range="0 0.21" actuatorfrcrange="-500 500"/>
          <geom type="mesh" contype="0" conaffinity="0" group="1" density="0" rgba="0.792157 0.819608 0.933333 1" mesh="LZ_it_Link"/>
          <geom pos="-0.0013627 -0.00020167 0.008" quat="1 0 0 0" type="mesh" contype="0" conaffinity="0" group="1" density="0" rgba="0.792157 0.819608 0.933333 1" mesh="Pitching_Link"/>
          <geom pos="-0.0013627 -0.00020167 0.008" quat="1 0 0 0" type="mesh" rgba="0.792157 0.819608 0.933333 1" mesh="Pitching_Link"/>
          <body name="Yaw_Link" pos="0.0541373 1.483e-05 0.074">
            <inertial pos="7.4e-05 -0.00062 0.071221" quat="0.999749 -0.0223799 0.000227644 -0.000701156" mass="1.144" diaginertia="0.00260247 0.0022047 0.00122659"/>
            <joint name="Yaw_Joint" pos="0 0 0" axis="0 1 0" range="-0.04363 2.3562" actuatorfrcrange="-80 80"/>
            <geom type="mesh" contype="0" conaffinity="0" group="1" density="0" rgba="0.792157 0.819608 0.933333 1" mesh="Yaw_Link"/>
            <geom type="mesh" rgba="0.792157 0.819608 0.933333 1" mesh="Yaw_Link"/>
            <body name="left_hip_sphere" pos="0.0 0.1 0.0">
              <geom type="sphere" size="0.01" contype="0" conaffinity="0" group="1" density="0" rgba="1 0 0 0"/>
              <body name="left_knee_sphere" pos="0.0 0.0 -0.2">
                <geom type="sphere" size="0.01" contype="0" conaffinity="0" group="1" density="0" rgba="1 0 0 0"/>
              </body>
            </body>
            <body name="right_hip_sphere" pos="0.0 -0.1 0.0">
              <geom type="sphere" size="0.01" contype="0" conaffinity="0" group="1" density="0" rgba="1 0 0 0"/>
              <body name="right_knee_sphere" pos="0.0 0.0 -0.2">
                <geom type="sphere" size="0.01" contype="0" conaffinity="0" group="1" density="0" rgba="1 0 0 0"/>
              </body>
            </body>
            
            <body name="torso_link" pos="-0.0023536 -4.8782e-05 0.104009">
              <inertial pos="0.00270075 0.000679835 0.179834" quat="0.999922 -0.00504418 0.0109932 -0.0030196" mass="9.599" diaginertia="0.124074 0.111984 0.0325788"/>
              <joint name="torso_Joint" pos="0 0 0" axis="0 0 1" range="-2.7053 2.7053" actuatorfrcrange="-30 30"/>
              <geom type="mesh" contype="0" conaffinity="0" group="1" density="0" rgba="0.7 0.7 0.7 1" mesh="torso_link"/>
              <geom type="mesh" rgba="0.7 0.7 0.7 1" mesh="torso_link"/>
              <geom pos="0.0039635 0 -0.054" quat="1 0 0 0" type="mesh" contype="0" conaffinity="0" group="1" density="0" rgba="0.2 0.2 0.2 1" mesh="logo_link"/>
              <geom pos="0.0039635 0 -0.054" quat="1 0 0 0" type="mesh" rgba="0.2 0.2 0.2 1" mesh="logo_link"/>
              <geom pos="0.0039635 0 -0.054" type="mesh" contype="0" conaffinity="0" group="1" density="0" rgba="0.2 0.2 0.2 1" mesh="head_link"/>
              <geom pos="0.0039635 0 -0.054" type="mesh" rgba="0.2 0.2 0.2 1" mesh="head_link"/>
              <body name="neck_sphere" pos="0 0 0.247">
                <geom type="sphere" size="0.035" contype="0" conaffinity="0" group="1" density="0" rgba="0.6 0.6 0.6 1"/>
                <body name="head_sphere" pos="0 0 0.16">
                  <geom type="sphere" size="0.035" contype="0" conaffinity="0" group="1" density="0" rgba="0.6 0.6 0.6 1"/>
                </body>
              </body>
              <body name="left_shoulder_pitch_link" pos="0.0039563 0.10022 0.24778" quat="0.990264 0.139201 1.38722e-05 -9.86868e-05">
                <inertial pos="0 0.035892 -0.011628" quat="0.654152 0.0130458 -0.326267 0.68225" mass="0.718" diaginertia="0.000465864 0.000432842 0.000406394"/>
                <joint name="left_shoulder_pitch_joint" pos="0 0 0" axis="0 1 0" range="-3.0892 2.6704" actuatorfrcrange="-25 25"/>
                <geom type="mesh" contype="0" conaffinity="0" group="1" density="0" rgba="0.7 0.7 0.7 1" mesh="left_shoulder_pitch_link"/>
                <geom size="0.03 0.025" pos="0 0.04 -0.01" quat="0.707107 0 0.707107 0" type="cylinder" rgba="0.7 0.7 0.7 1"/>
                <body name="left_shoulder_roll_link" pos="0 0.038 -0.013831" quat="0.990268 -0.139172 0 0">
                  <inertial pos="-0.000227 0.00727 -0.063243" quat="0.701256 -0.0196223 -0.00710317 0.712604" mass="0.643" diaginertia="0.000691311 0.000618011 0.000388977"/>
                  <joint name="left_shoulder_roll_joint" pos="0 0 0" axis="1 0 0" range="-1.5882 2.2515" actuatorfrcrange="-25 25"/>
                  <geom type="mesh" contype="0" conaffinity="0" group="1" density="0" rgba="0.7 0.7 0.7 1" mesh="left_shoulder_roll_link"/>
                  <geom size="0.03 0.015" pos="-0.004 0.006 -0.053" type="cylinder" rgba="0.7 0.7 0.7 1"/>
                  <body name="left_shoulder_yaw_link" pos="0 0.00624 -0.1032">
                    <inertial pos="0.010773 -0.002949 -0.072009" quat="0.716879 -0.0964829 -0.0679942 0.687134" mass="0.734" diaginertia="0.00106187 0.00103217 0.000400661"/>
                    <joint name="left_shoulder_yaw_joint" pos="0 0 0" axis="0 0 1" range="-2.618 2.618" actuatorfrcrange="-25 25"/>
                    <geom type="mesh" contype="0" conaffinity="0" group="1" density="0" rgba="0.7 0.7 0.7 1" mesh="left_shoulder_yaw_link"/>
                    <geom type="mesh" rgba="0.7 0.7 0.7 1" mesh="left_shoulder_yaw_link"/>
                    <body name="left_elbow_link" pos="0.015783 0 -0.080518">
                      <inertial pos="0.064956 0.004454 -0.010062" quat="0.541765 0.636132 0.388821 0.388129" mass="0.6" diaginertia="0.000443035 0.000421612 0.000259353"/>
                      <joint name="left_elbow_joint" pos="0 0 0" axis="0 1 0" range="-1.0472 2.0944" actuatorfrcrange="-25 25"/>
                      <geom type="mesh" contype="0" conaffinity="0" group="1" density="0" rgba="0.7 0.7 0.7 1" mesh="left_elbow_link"/>
                      <geom type="mesh" rgba="0.7 0.7 0.7 1" mesh="left_elbow_link"/>
                      <body name="left_wrist_roll_link" pos="0.1 0.00188791 -0.01">
                        <inertial pos="0.0171394 0.000537591 4.8864e-07" quat="0.575338 0.411667 -0.574906 0.411094" mass="0.085445" diaginertia="5.48211e-05 4.96646e-05 3.57798e-05"/>
                        <joint name="left_wrist_roll_joint" pos="0 0 0" axis="1 0 0" range="-1.97222 1.97222" actuatorfrcrange="-25 25"/>
                        <geom type="mesh" contype="0" conaffinity="0" group="1" density="0" rgba="0.7 0.7 0.7 1" mesh="left_wrist_roll_link"/>
                        <geom type="mesh" rgba="0.7 0.7 0.7 1" mesh="left_wrist_roll_link"/>
                        <body name="left_wrist_pitch_link" pos="0.038 0 0">
                          <inertial pos="0.0229999 -0.00111685 -0.00111658" quat="0.249998 0.661363 0.293036 0.643608" mass="0.48405" diaginertia="0.000430353 0.000429873 0.000164648"/>
                          <joint name="left_wrist_pitch_joint" pos="0 0 0" axis="0 1 0" range="-1.61443 1.61443" actuatorfrcrange="-5 5"/>
                          <geom type="mesh" contype="0" conaffinity="0" group="1" density="0" rgba="0.7 0.7 0.7 1" mesh="left_wrist_pitch_link"/>
                          <geom type="mesh" rgba="0.7 0.7 0.7 1" mesh="left_wrist_pitch_link"/>
                          <body name="left_wrist_yaw_link" pos="0.046 0 0">
                            <inertial pos="0.0526434 0.0334441 0.00200537" quat="0.411983 0.383578 0.586947 0.581921" mass="0.457415" diaginertia="0.000744818 0.000645509 0.000389649"/>
                            <joint name="left_wrist_yaw_joint" pos="0 0 0" axis="0 0 1" range="-1.61443 1.61443" actuatorfrcrange="-5 5"/>
                            <geom type="mesh" contype="0" conaffinity="0" group="1" density="0" rgba="0.7 0.7 0.7 1" mesh="left_wrist_yaw_link"/>
                            <geom type="mesh" rgba="0.7 0.7 0.7 1" mesh="left_wrist_yaw_link"/>
                            <geom pos="0.0415 0.003 0" quat="1 0 0 0" type="mesh" contype="0" conaffinity="0" group="1" density="0" rgba="0.7 0.7 0.7 1" mesh="left_hand_palm_link"/>
                            <geom pos="0.0415 0.003 0" quat="1 0 0 0" type="mesh" rgba="0.7 0.7 0.7 1" mesh="left_hand_palm_link"/>
                            <body name="left_hand_thumb_0_link" pos="0.067 0.003 0">
                              <inertial pos="-0.000884246 -0.00863407 0.000944293" quat="0.462991 0.643965 -0.460173 0.398986" mass="0.0862366" diaginertia="1.6546e-05 1.60058e-05 1.43741e-05"/>
                              <!-- <joint name="left_hand_thumb_0_joint" pos="0 0 0" axis="0 1 0" range="-1.0472 1.0472" actuatorfrcrange="-2.45 2.45"/> -->
                              <geom type="mesh" contype="0" conaffinity="0" group="1" density="0" rgba="0.7 0.7 0.7 1" mesh="left_hand_thumb_0_link"/>
                              <geom type="mesh" rgba="0.7 0.7 0.7 1" mesh="left_hand_thumb_0_link"/>
                              <body name="left_hand_thumb_1_link" pos="-0.0025 -0.0193 0">
                                <inertial pos="-0.000827888 -0.0354744 -0.0003809" quat="0.685598 0.705471 -0.15207 0.0956069" mass="0.0588507" diaginertia="1.28514e-05 1.22902e-05 5.9666e-06"/>
                                <!-- <joint name="left_hand_thumb_1_joint" pos="0 0 0" axis="0 0 1" range="-0.724312 1.0472" actuatorfrcrange="-1.4 1.4"/> -->
                                <geom type="mesh" contype="0" conaffinity="0" group="1" density="0" rgba="0.7 0.7 0.7 1" mesh="left_hand_thumb_1_link"/>
                                <geom size="0.01 0.015 0.01" pos="-0.001 -0.032 0" type="box" rgba="0.7 0.7 0.7 1"/>
                                <body name="left_hand_thumb_2_link" pos="0 -0.0458 0">
                                  <inertial pos="-0.00171735 -0.0262819 0.000107789" quat="0.703174 0.710977 -0.00017564 -0.00766553" mass="0.0203063" diaginertia="4.61314e-06 3.86645e-06 1.53495e-06"/>
                                  <!-- <joint name="left_hand_thumb_2_joint" pos="0 0 0" axis="0 0 1" range="0 1.74533" actuatorfrcrange="-1.4 1.4"/> -->
                                  <geom type="mesh" contype="0" conaffinity="0" group="1" density="0" rgba="0.7 0.7 0.7 1" mesh="left_hand_thumb_2_link"/>
                                  <geom type="mesh" rgba="0.7 0.7 0.7 1" mesh="left_hand_thumb_2_link"/>
                                </body>
                              </body>
                            </body>
                            <body name="left_hand_middle_0_link" pos="0.1192 0.0046 -0.0285">
                              <inertial pos="0.0354744 0.000827888 0.0003809" quat="0.391313 0.552395 0.417187 0.606373" mass="0.0588507" diaginertia="1.28514e-05 1.22902e-05 5.9666e-06"/>
                              <!-- <joint name="left_hand_middle_0_joint" pos="0 0 0" axis="0 0 1" range="-1.5708 0" actuatorfrcrange="-1.4 1.4"/> -->
                              <geom type="mesh" contype="0" conaffinity="0" group="1" density="0" rgba="0.7 0.7 0.7 1" mesh="left_hand_middle_0_link"/>
                              <geom type="mesh" rgba="0.7 0.7 0.7 1" mesh="left_hand_middle_0_link"/>
                              <body name="left_hand_middle_1_link" pos="0.0458 0 0">
                                <inertial pos="0.0262819 0.00171735 -0.000107789" quat="0.502612 0.491799 0.502639 0.502861" mass="0.0203063" diaginertia="4.61314e-06 3.86645e-06 1.53495e-06"/>
                                <!-- <joint name="left_hand_middle_1_joint" pos="0 0 0" axis="0 0 1" range="-1.74533 0" actuatorfrcrange="-1.4 1.4"/> -->
                                <geom type="mesh" contype="0" conaffinity="0" group="1" density="0" rgba="0.7 0.7 0.7 1" mesh="left_hand_middle_1_link"/>
                                <geom type="mesh" rgba="0.7 0.7 0.7 1" mesh="left_hand_middle_1_link"/>
                              </body>
                            </body>
                            <body name="left_hand_index_0_link" pos="0.1192 0.0046 0.0285">
                              <inertial pos="0.0354744 0.000827888 0.0003809" quat="0.391313 0.552395 0.417187 0.606373" mass="0.0588507" diaginertia="1.28514e-05 1.22902e-05 5.9666e-06"/>
                              <!-- <joint name="left_hand_index_0_joint" pos="0 0 0" axis="0 0 1" range="-1.5708 0" actuatorfrcrange="-1.4 1.4"/> -->
                              <geom type="mesh" contype="0" conaffinity="0" group="1" density="0" rgba="0.7 0.7 0.7 1" mesh="left_hand_index_0_link"/>
                              <geom type="mesh" rgba="0.7 0.7 0.7 1" mesh="left_hand_index_0_link"/>
                              <body name="left_hand_index_1_link" pos="0.0458 0 0">
                                <inertial pos="0.0262819 0.00171735 -0.000107789" quat="0.502612 0.491799 0.502639 0.502861" mass="0.0203063" diaginertia="4.61314e-06 3.86645e-06 1.53495e-06"/>
                                <!-- <joint name="left_hand_index_1_joint" pos="0 0 0" axis="0 0 1" range="-1.74533 0" actuatorfrcrange="-1.4 1.4"/> -->
                                <geom type="mesh" contype="0" conaffinity="0" group="1" density="0" rgba="0.7 0.7 0.7 1" mesh="left_hand_index_1_link"/>
                                <geom type="mesh" rgba="0.7 0.7 0.7 1" mesh="left_hand_index_1_link"/>
                              </body>
                            </body>
                          </body>
                        </body>
                      </body>
                    </body>
                  </body>
                </body>
              </body>
              <body name="right_shoulder_pitch_link" pos="0.0039563 -0.10021 0.24778" quat="0.990264 -0.139201 1.38722e-05 9.86868e-05">
                <inertial pos="0 -0.035892 -0.011628" quat="0.68225 -0.326267 0.0130458 0.654152" mass="0.718" diaginertia="0.000465864 0.000432842 0.000406394"/>
                <joint name="right_shoulder_pitch_joint" pos="0 0 0" axis="0 1 0" range="-3.0892 2.6704" actuatorfrcrange="-25 25"/>
                <geom type="mesh" contype="0" conaffinity="0" group="1" density="0" rgba="0.7 0.7 0.7 1" mesh="right_shoulder_pitch_link"/>
                <geom size="0.03 0.025" pos="0 -0.04 -0.01" quat="0.707107 0 0.707107 0" type="cylinder" rgba="0.7 0.7 0.7 1"/>
                <body name="right_shoulder_roll_link" pos="0 -0.038 -0.013831" quat="0.990268 0.139172 0 0">
                  <inertial pos="-0.000227 -0.00727 -0.063243" quat="0.712604 -0.00710317 -0.0196223 0.701256" mass="0.643" diaginertia="0.000691311 0.000618011 0.000388977"/>
                  <joint name="right_shoulder_roll_joint" pos="0 0 0" axis="1 0 0" range="-2.2515 1.5882" actuatorfrcrange="-25 25"/>
                  <geom type="mesh" contype="0" conaffinity="0" group="1" density="0" rgba="0.7 0.7 0.7 1" mesh="right_shoulder_roll_link"/>
                  <geom size="0.03 0.015" pos="-0.004 -0.006 -0.053" type="cylinder" rgba="0.7 0.7 0.7 1"/>
                  <body name="right_shoulder_yaw_link" pos="0 -0.00624 -0.1032">
                    <inertial pos="0.010773 0.002949 -0.072009" quat="0.687134 -0.0679942 -0.0964829 0.716879" mass="0.734" diaginertia="0.00106187 0.00103217 0.000400661"/>
                    <joint name="right_shoulder_yaw_joint" pos="0 0 0" axis="0 0 1" range="-2.618 2.618" actuatorfrcrange="-25 25"/>
                    <geom type="mesh" contype="0" conaffinity="0" group="1" density="0" rgba="0.7 0.7 0.7 1" mesh="right_shoulder_yaw_link"/>
                    <geom type="mesh" rgba="0.7 0.7 0.7 1" mesh="right_shoulder_yaw_link"/>
                    <body name="right_elbow_link" pos="0.015783 0 -0.080518">
                      <inertial pos="0.064956 -0.004454 -0.010062" quat="0.388129 0.388821 0.636132 0.541765" mass="0.6" diaginertia="0.000443035 0.000421612 0.000259353"/>
                      <joint name="right_elbow_joint" pos="0 0 0" axis="0 1 0" range="-1.0472 2.0944" actuatorfrcrange="-25 25"/>
                      <geom type="mesh" contype="0" conaffinity="0" group="1" density="0" rgba="0.7 0.7 0.7 1" mesh="right_elbow_link"/>
                      <geom type="mesh" rgba="0.7 0.7 0.7 1" mesh="right_elbow_link"/>
                      <body name="right_wrist_roll_link" pos="0.1 -0.00188791 -0.01">
                        <inertial pos="0.0171394 -0.000537591 4.8864e-07" quat="0.411667 0.575338 -0.411094 0.574906" mass="0.085445" diaginertia="5.48211e-05 4.96646e-05 3.57798e-05"/>
                        <joint name="right_wrist_roll_joint" pos="0 0 0" axis="1 0 0" range="-1.97222 1.97222" actuatorfrcrange="-25 25"/>
                        <geom type="mesh" contype="0" conaffinity="0" group="1" density="0" rgba="0.7 0.7 0.7 1" mesh="right_wrist_roll_link"/>
                        <geom type="mesh" rgba="0.7 0.7 0.7 1" mesh="right_wrist_roll_link"/>
                        <body name="right_wrist_pitch_link" pos="0.038 0 0">
                          <inertial pos="0.0229999 0.00111685 -0.00111658" quat="0.643608 0.293036 0.661363 0.249998" mass="0.48405" diaginertia="0.000430353 0.000429873 0.000164648"/>
                          <joint name="right_wrist_pitch_joint" pos="0 0 0" axis="0 1 0" range="-1.61443 1.61443" actuatorfrcrange="-5 5"/>
                          <geom type="mesh" contype="0" conaffinity="0" group="1" density="0" rgba="0.7 0.7 0.7 1" mesh="right_wrist_pitch_link"/>
                          <geom type="mesh" rgba="0.7 0.7 0.7 1" mesh="right_wrist_pitch_link"/>
                          <body name="right_wrist_yaw_link" pos="0.046 0 0">
                            <inertial pos="0.0568045 0.0340904 -0.0027545" quat="0.373005 0.447177 0.575372 0.574323" mass="0.457415" diaginertia="0.000764115 0.000685792 0.000411311"/>
                            <joint name="right_wrist_yaw_joint" pos="0 0 0" axis="0 0 1" range="-1.61443 1.61443" actuatorfrcrange="-5 5"/>
                            <geom type="mesh" contype="0" conaffinity="0" group="1" density="0" rgba="0.7 0.7 0.7 1" mesh="right_wrist_yaw_link"/>
                            <geom type="mesh" rgba="0.7 0.7 0.7 1" mesh="right_wrist_yaw_link"/>
                            <geom pos="0.0415 -0.003 0" quat="1 0 0 0" type="mesh" contype="0" conaffinity="0" group="1" density="0" rgba="0.7 0.7 0.7 1" mesh="right_hand_palm_link"/>
                            <geom pos="0.0415 -0.003 0" quat="1 0 0 0" type="mesh" rgba="0.7 0.7 0.7 1" mesh="right_hand_palm_link"/>
                            <body name="right_hand_thumb_0_link" pos="0.067 -0.003 0">
                              <inertial pos="-0.000884246 0.00863407 0.000944293" quat="0.643965 0.462991 -0.398986 0.460173" mass="0.0862366" diaginertia="1.6546e-05 1.60058e-05 1.43741e-05"/>
                              <!-- <joint name="right_hand_thumb_0_joint" pos="0 0 0" axis="0 1 0" range="-1.0472 1.0472" actuatorfrcrange="-2.45 2.45"/> -->
                              <geom type="mesh" contype="0" conaffinity="0" group="1" density="0" rgba="0.7 0.7 0.7 1" mesh="right_hand_thumb_0_link"/>
                              <geom type="mesh" rgba="0.7 0.7 0.7 1" mesh="right_hand_thumb_0_link"/>
                              <body name="right_hand_thumb_1_link" pos="-0.0025 0.0193 0">
                                <inertial pos="-0.000827888 0.0354744 -0.0003809" quat="0.705471 0.685598 -0.0956069 0.15207" mass="0.0588507" diaginertia="1.28514e-05 1.22902e-05 5.9666e-06"/>
                                <!-- <joint name="right_hand_thumb_1_joint" pos="0 0 0" axis="0 0 1" range="-1.0472 0.724312" actuatorfrcrange="-1.4 1.4"/> -->
                                <geom type="mesh" contype="0" conaffinity="0" group="1" density="0" rgba="0.7 0.7 0.7 1" mesh="right_hand_thumb_1_link"/>
                                <geom size="0.01 0.015 0.01" pos="-0.001 0.032 0" type="box" rgba="0.7 0.7 0.7 1"/>
                                <body name="right_hand_thumb_2_link" pos="0 0.0458 0">
                                  <inertial pos="-0.00171735 0.0262819 0.000107789" quat="0.710977 0.703174 0.00766553 0.00017564" mass="0.0203063" diaginertia="4.61314e-06 3.86645e-06 1.53495e-06"/>
                                  <!-- <joint name="right_hand_thumb_2_joint" pos="0 0 0" axis="0 0 1" range="-1.74533 0" actuatorfrcrange="-1.4 1.4"/> -->
                                  <geom type="mesh" contype="0" conaffinity="0" group="1" density="0" rgba="0.7 0.7 0.7 1" mesh="right_hand_thumb_2_link"/>
                                  <geom type="mesh" rgba="0.7 0.7 0.7 1" mesh="right_hand_thumb_2_link"/>
                                </body>
                              </body>
                            </body>
                            <body name="right_hand_middle_0_link" pos="0.1192 -0.0046 -0.0285">
                              <inertial pos="0.0354744 -0.000827888 0.0003809" quat="0.606373 0.417187 0.552395 0.391313" mass="0.0588507" diaginertia="1.28514e-05 1.22902e-05 5.9666e-06"/>
                              <!-- <joint name="right_hand_middle_0_joint" pos="0 0 0" axis="0 0 1" range="0 1.5708" actuatorfrcrange="-1.4 1.4"/> -->
                              <geom type="mesh" contype="0" conaffinity="0" group="1" density="0" rgba="0.7 0.7 0.7 1" mesh="right_hand_middle_0_link"/>
                              <geom type="mesh" rgba="0.7 0.7 0.7 1" mesh="right_hand_middle_0_link"/>
                              <body name="right_hand_middle_1_link" pos="0.0458 0 0">
                                <inertial pos="0.0262819 -0.00171735 -0.000107789" quat="0.502861 0.502639 0.491799 0.502612" mass="0.0203063" diaginertia="4.61314e-06 3.86645e-06 1.53495e-06"/>
                                <!-- <joint name="right_hand_middle_1_joint" pos="0 0 0" axis="0 0 1" range="0 1.74533" actuatorfrcrange="-1.4 1.4"/> -->
                                <geom type="mesh" contype="0" conaffinity="0" group="1" density="0" rgba="0.7 0.7 0.7 1" mesh="right_hand_middle_1_link"/>
                                <geom type="mesh" rgba="0.7 0.7 0.7 1" mesh="right_hand_middle_1_link"/>
                              </body>
                            </body>
                            <body name="right_hand_index_0_link" pos="0.1192 -0.0046 0.0285">
                              <inertial pos="0.0354744 -0.000827888 0.0003809" quat="0.606373 0.417187 0.552395 0.391313" mass="0.0588507" diaginertia="1.28514e-05 1.22902e-05 5.9666e-06"/>
                              <!-- <joint name="right_hand_index_0_joint" pos="0 0 0" axis="0 0 1" range="0 1.5708" actuatorfrcrange="-1.4 1.4"/> -->
                              <geom type="mesh" contype="0" conaffinity="0" group="1" density="0" rgba="0.7 0.7 0.7 1" mesh="right_hand_index_0_link"/>
                              <geom type="mesh" rgba="0.7 0.7 0.7 1" mesh="right_hand_index_0_link"/>
                              <body name="right_hand_index_1_link" pos="0.0458 0 0">
                                <inertial pos="0.0262819 -0.00171735 -0.000107789" quat="0.502861 0.502639 0.491799 0.502612" mass="0.0203063" diaginertia="4.61314e-06 3.86645e-06 1.53495e-06"/>
                                <!-- <joint name="right_hand_index_1_joint" pos="0 0 0" axis="0 0 1" range="0 1.74533" actuatorfrcrange="-1.4 1.4"/> -->
                                <geom type="mesh" contype="0" conaffinity="0" group="1" density="0" rgba="0.7 0.7 0.7 1" mesh="right_hand_index_1_link"/>
                                <geom type="mesh" rgba="0.7 0.7 0.7 1" mesh="right_hand_index_1_link"/>
                              </body>
                            </body>
                          </body>
                        </body>
                      </body>
                    </body>
                  </body>
                </body>
              </body>
            </body>
          </body>
        </body>
      </body>
    </body>
  </worldbody>

  <actuator>
    <!-- <motor name="Left_Wheel_Joint" joint="Left_Wheel_Joint"/> -->
    <!-- <motor name="Right_Wheel_Joint" joint="Right_Wheel_Joint"/> -->
    <motor name="LZ_mt_Joint" joint="LZ_mt_Joint"/>
    <motor name="LZ_it_Joint" joint="LZ_it_Joint"/>
    <motor name="Yaw_Joint" joint="Yaw_Joint"/>
    <motor name="torso_Joint" joint="torso_Joint"/>
    <motor name="left_shoulder_pitch_joint" joint="left_shoulder_pitch_joint"/>
    <motor name="left_shoulder_roll_joint" joint="left_shoulder_roll_joint"/>
    <motor name="left_shoulder_yaw_joint" joint="left_shoulder_yaw_joint"/>
    <motor name="left_elbow_joint" joint="left_elbow_joint"/>
    <motor name="left_wrist_roll_joint" joint="left_wrist_roll_joint"/>
    <motor name="left_wrist_pitch_joint" joint="left_wrist_pitch_joint"/>
    <motor name="left_wrist_yaw_joint" joint="left_wrist_yaw_joint"/>
    <motor name="right_shoulder_pitch_joint" joint="right_shoulder_pitch_joint"/>
    <motor name="right_shoulder_roll_joint" joint="right_shoulder_roll_joint"/>
    <motor name="right_shoulder_yaw_joint" joint="right_shoulder_yaw_joint"/>
    <motor name="right_elbow_joint" joint="right_elbow_joint"/>
    <motor name="right_wrist_roll_joint" joint="right_wrist_roll_joint"/>
    <motor name="right_wrist_pitch_joint" joint="right_wrist_pitch_joint"/>
    <motor name="right_wrist_yaw_joint" joint="right_wrist_yaw_joint"/>
  </actuator>

  <!-- setup scene -->
  <statistic center="1.0 0.7 1.0" extent="0.8"/>
  <visual>
    <headlight diffuse="0.6 0.6 0.6" ambient="0.1 0.1 0.1" specular="0.9 0.9 0.9"/>
    <rgba haze="0.15 0.25 0.35 1"/>
    <global azimuth="-140" elevation="-20"/>
  </visual>
  <asset>
    <texture type="skybox" builtin="flat" rgb1="0 0 0" rgb2="0 0 0" width="512" height="3072"/>
    <texture type="2d" name="groundplane" builtin="checker" mark="edge" rgb1="0.2 0.3 0.4" rgb2="0.1 0.2 0.3" markrgb="0.8 0.8 0.8" width="300" height="300"/>
    <material name="groundplane" texture="groundplane" texuniform="true" texrepeat="5 5" reflectance="0.2"/>
  </asset>
  <worldbody>
    <light pos="1 0 3.5" dir="0 0 -1" directional="true"/>
    <geom name="floor" size="0 0 0.05" type="plane" material="groundplane" friction="0.75 0.02 0.001"/>
  </worldbody>
</mujoco>
