<mujoco model="X2-0807urdf">
  <compiler angle="radian" meshdir="meshes/"/>

  <asset>
    <mesh name="base_link" file="base_link.STL"/>
    <mesh name="left_front_Link1" file="left_front_Link1.STL"/>
    <mesh name="left_front_Link2" file="left_front_Link2.STL"/>
    <mesh name="left_front_Link3" file="left_front_Link3.STL"/>
    <mesh name="left_front_Link4" file="left_front_Link4.STL"/>
    <mesh name="left_hind_Link1" file="left_hind_Link1.STL"/>
    <mesh name="left_hind_Link2" file="left_hind_Link2.STL"/>
    <mesh name="left_hind_Link3" file="left_hind_Link3.STL"/>
    <mesh name="left_hind_Link4" file="left_hind_Link4.STL"/>
    <mesh name="right_front_Link1" file="right_front_Link1.STL"/>
    <mesh name="right_front_Link2" file="right_front_Link2.STL"/>
    <mesh name="right_front_Link3" file="right_front_Link3.STL"/>
    <mesh name="right_front_Link4" file="right_front_Link4.STL"/>
    <mesh name="right_hind_Link1" file="right_hind_Link1.STL"/>
    <mesh name="right_hind_Link2" file="right_hind_Link2.STL"/>
    <mesh name="right_hind_Link3" file="right_hind_Link3.STL"/>
    <mesh name="right_hind_Link4" file="right_hind_Link4.STL"/>
  </asset>

  <worldbody>
    <body name="base_link" pos="0 0 0.8">
      <inertial pos="0.00697549 -0.000712133 0.0128764" quat="-0.00152806 0.699581 -0.00252911 0.714547" mass="19.671" diaginertia="0.474399 0.409727 0.14363"/>
      <joint name="floating_base_joint" type="free"/>
      <geom type="mesh" contype="0" conaffinity="0" group="1" density="0" rgba="0.792157 0.819608 0.933333 1" mesh="base_link"/>
      <geom size="0.12 0.14 0.08" pos="0 0 0.01" type="box" rgba="0.792157 0.819608 0.933333 1"/>
      <geom size="0.025 0.05 0.005" pos="0.365 0 0.1" quat="0.939373 0 -0.342898 0" type="box"/>
      <geom size="0.04" pos="0.345 0 0.08"/>
      <geom size="0.04" pos="0.25 0 0.09"/>
      <geom size="0.025 0.05 0.005" pos="-0.302 0 0.112" quat="0.939373 0 0.342898 0" type="box"/>
      <geom size="0.04" pos="-0.285 0 0.08"/>
      <geom size="0.04" pos="-0.19 0 0.09"/>
      <body name="hips_sphere" pos="-0.25944 0.0 0">
        <geom type="sphere" size="0.035" contype="0" conaffinity="0" group="1" density="0" rgba="0.6 0.6 0.6 0.0"/>
      </body>
      <body name="neck_sphere" pos="0.25944 0.0 0">
        <geom type="sphere" size="0.035" contype="0" conaffinity="0" group="1" density="0" rgba="0.6 0.6 0.6 0.0"/>
      </body>
      <body name="head_sphere" pos="0.3 0.0 0">
        <geom type="sphere" size="0.035" contype="0" conaffinity="0" group="1" density="0" rgba="0.6 0.6 0.6 0.0"/>
      </body>
      <body name="FL_hip" pos="0.25944 0.075113 0">
        <inertial pos="-0.002408 -0.01622 0.000239" quat="0.66751 0.421649 0.565191 0.239168" mass="1.62" diaginertia="0.0016644 0.00161602 0.00145995"/>
        <joint name="FL_hip_joint" pos="0 0 0" axis="1 0 0" range="-1.01 1.01" actuatorfrcrange="-120 120"/>
        <geom type="mesh" contype="0" conaffinity="0" group="1" density="0" rgba="0.898039 0.917647 0.929412 1" mesh="left_front_Link1"/>
        <geom size="0.046 0.06" pos="0 0.085 0" quat="0.707035 0.707179 0 0" type="cylinder" rgba="0.898039 0.917647 0.929412 1"/>
        <geom size="0.045 0.03" pos="0 -0.01 0" quat="0.707035 0.707179 0 0" type="cylinder" rgba="0.898039 0.917647 0.929412 1"/>
        <body name="FL_thigh" pos="0 0.12779 0">
          <inertial pos="-0.003268 -0.03111 -0.053896" quat="0.993045 0.11348 0.0231928 0.0211279" mass="3.079" diaginertia="0.0293395 0.0280448 0.00383794"/>
          <joint name="FL_thigh_joint" pos="0 0 0" axis="0 1 0" range="-2.34 3.15" actuatorfrcrange="-120 120"/>
          <geom type="mesh" contype="0" conaffinity="0" group="1" density="0" rgba="0.898039 0.917647 0.929412 1" mesh="left_front_Link2"/>
          <geom size="0.023 0.023 0.07" pos="-0.025 -0.003 -0.12" type="box" rgba="0.898039 0.917647 0.929412 1"/>
          <geom size="0.0085 0.025 0.03" pos="-0.022 0 -0.275" quat="0.930508 0 -0.366273 0" type="box" rgba="0.898039 0.917647 0.929412 1"/>
          <body name="FL_calf" pos="0 0 -0.275">
            <inertial pos="0.004018 0.017411 -0.232283" quat="0.775901 0.051812 -0.0143577 0.628559" mass="1.751" diaginertia="0.0147479 0.0144066 0.00134515"/>
            <joint name="FL_calf_joint" pos="0 0 0" axis="0 1 0" range="-2.77 -0.54" actuatorfrcrange="-180 180"/>
            <geom type="mesh" contype="0" conaffinity="0" group="1" density="0" rgba="0.792157 0.819608 0.933333 1" mesh="left_front_Link3"/>
            <geom size="0.05 0.015" pos="0 0 -0.275" quat="0.707035 0.707179 0 0" type="cylinder" rgba="0.792157 0.819608 0.933333 1"/>
            <geom size="0.011 0.015 0.05" pos="0.02 0 -0.08" quat="0.992809 0 -0.119712 0" type="box" rgba="0.792157 0.819608 0.933333 1"/>
            <geom size="0.011 0.015 0.04" pos="0.033 0 -0.17" quat="0.999888 0 -0.0149994 0" type="box" rgba="0.792157 0.819608 0.933333 1"/>
            <geom size="0.014 0.02 0.02" pos="0.027 0 -0.23" quat="0.995004 0 0.0998334 0" type="box" rgba="0.792157 0.819608 0.933333 1"/>
            <body name="FL_wheel" pos="0 0 -0.275">
              <inertial pos="0 0.05108 0" quat="0.707107 0 0 0.707107" mass="0.982" diaginertia="0.00458159 0.00243576 0.00243576"/>
              <joint name="FL_wheel_joint" pos="0 0 0" axis="0 1 0" range="-inf inf" actuatorfrcrange="-24.5 24.5"/>
              <geom type="mesh" contype="0" conaffinity="0" group="1" density="0" rgba="0.792157 0.819608 0.933333 1" mesh="left_front_Link4"/>
              <geom size="0.035" pos="0.0 0.05 -0.1" contype="0" conaffinity="0" group="1" density="0" rgba="1 0 0 1"/>
              <geom type="mesh" rgba="1 0 0 1" mesh="left_front_Link4"/>
              <body name="left_hand" pos="0.0 0.05 -0.1">
                <geom type="sphere" size="0.035" contype="0" conaffinity="0" group="1" density="0" rgba="0.6 0.6 0.6 0.0"/>
              </body>
            </body>
          </body>
        </body>
      </body>
      <body name="RL_hip" pos="-0.25944 0.075113 0">
        <inertial pos="0.00327 -0.01622 -9.7e-05" quat="0.358494 0.383537 0.580824 0.622113" mass="1.62" diaginertia="0.00167848 0.00163116 0.00141504"/>
        <joint name="RL_hip_joint" pos="0 0 0" axis="1 0 0" range="-1.01 1.01" actuatorfrcrange="-120 120"/>
        <geom type="mesh" contype="0" conaffinity="0" group="1" density="0" rgba="0.898039 0.917647 0.929412 1" mesh="left_hind_Link1"/>
        <geom size="0.046 0.06" pos="0 0.085 0" quat="0.707035 0.707179 0 0" type="cylinder" rgba="0.898039 0.917647 0.929412 1"/>
        <geom size="0.045 0.03" pos="0 -0.01 0" quat="0.707035 0.707179 0 0" type="cylinder" rgba="0.898039 0.917647 0.929412 1"/>
        <body name="RL_thigh" pos="0 0.12779 0">
          <inertial pos="-0.003268 -0.03111 -0.053896" quat="0.993045 0.11348 0.0231928 0.0211279" mass="3.079" diaginertia="0.0293395 0.0280448 0.00383794"/>
          <joint name="RL_thigh_joint" pos="0 0 0" axis="0 1 0" range="-1.56 3.94" actuatorfrcrange="-120 120"/>
          <geom type="mesh" contype="0" conaffinity="0" group="1" density="0" rgba="0.898039 0.917647 0.929412 1" mesh="left_hind_Link2"/>
          <geom size="0.023 0.023 0.07" pos="-0.025 -0.003 -0.12" type="box" rgba="0.898039 0.917647 0.929412 1"/>
          <geom size="0.0085 0.025 0.03" pos="-0.022 0 -0.275" quat="0.930508 0 -0.366273 0" type="box" rgba="0.898039 0.917647 0.929412 1"/>
          <body name="RL_calf" pos="0 0 -0.275">
            <inertial pos="0.004018 0.017411 -0.232283" quat="0.775901 0.051812 -0.0143577 0.628559" mass="1.751" diaginertia="0.0147479 0.0144066 0.00134515"/>
            <joint name="RL_calf_joint" pos="0 0 0" axis="0 1 0" range="-2.77 -0.54" actuatorfrcrange="-180 180"/>
            <geom type="mesh" contype="0" conaffinity="0" group="1" density="0" rgba="0.792157 0.819608 0.933333 1" mesh="left_hind_Link3"/>
            <geom size="0.05 0.015" pos="0 0 -0.275" quat="0.707035 0.707179 0 0" type="cylinder" rgba="0.792157 0.819608 0.933333 1"/>
            <geom size="0.011 0.015 0.05" pos="0.02 0 -0.08" quat="0.992809 0 -0.119712 0" type="box" rgba="0.792157 0.819608 0.933333 1"/>
            <geom size="0.011 0.015 0.04" pos="0.033 0 -0.17" quat="0.999888 0 -0.0149994 0" type="box" rgba="0.792157 0.819608 0.933333 1"/>
            <geom size="0.014 0.02 0.02" pos="0.027 0 -0.23" quat="0.995004 0 0.0998334 0" type="box" rgba="0.792157 0.819608 0.933333 1"/>
            <body name="RL_wheel" pos="0 0 -0.275">
              <inertial pos="0 0.05108 0" quat="0.707107 0 0 0.707107" mass="0.982" diaginertia="0.00458159 0.00243576 0.00243576"/>
              <joint name="RL_wheel_joint" pos="0 0 0" axis="0 1 0" range="-inf inf" actuatorfrcrange="-24.5 24.5"/>
              <geom type="mesh" contype="0" conaffinity="0" group="1" density="0" rgba="0.792157 0.819608 0.933333 1" mesh="left_hind_Link4"/>
              <geom size="0.035" pos="0.0 0.05 -0.1" contype="0" conaffinity="0" group="1" density="0" rgba="1 0 0 1"/>
              <geom type="mesh" rgba="1 0 0 1" mesh="left_hind_Link4"/>
              <body name="left_foot" pos="0.0 0.05 -0.1">
                <geom type="sphere" size="0.035" contype="0" conaffinity="0" group="1" density="0" rgba="0.6 0.6 0.6 1"/>
                <body name="left_foot_end_link" pos="0.0 0 0.0">
                  <geom type="sphere" size="0.01" contype="0" conaffinity="0" group="1" density="0" rgba="1 0 0 0"/>
                </body>
                <body name="left_toe_link" pos="0.0 0 0.0">
                  <geom type="sphere" size="0.01" contype="0" conaffinity="0" group="1" density="0" rgba="1 0 0 0"/>
                </body>
              </body>
            </body>
          </body>
        </body>
      </body>
      <body name="FR_hip" pos="0.25944 -0.075113 0">
        <inertial pos="-0.002465 0.01622 0.000318" quat="0.244263 0.553086 0.449878 0.657299" mass="1.62" diaginertia="0.0016672 0.00160755 0.00146457"/>
        <joint name="FR_hip_joint" pos="0 0 0" axis="1 0 0" range="-1.01 1.01" actuatorfrcrange="-120 120"/>
        <geom type="mesh" contype="0" conaffinity="0" group="1" density="0" rgba="0.898039 0.917647 0.929412 1" mesh="right_front_Link1"/>
        <geom size="0.046 0.06" pos="0 -0.085 0" quat="0.707035 0.707179 0 0" type="cylinder" rgba="0.898039 0.917647 0.929412 1"/>
        <geom size="0.045 0.03" pos="0 0.01 0" quat="0.707035 0.707179 0 0" type="cylinder" rgba="0.898039 0.917647 0.929412 1"/>
        <body name="FR_thigh" pos="0 -0.12779 0">
          <inertial pos="-0.003256 0.031125 -0.053921" quat="0.993054 -0.113587 0.0234158 -0.0198545" mass="3.077" diaginertia="0.029323 0.028038 0.00383842"/>
          <joint name="FR_thigh_joint" pos="0 0 0" axis="0 1 0" range="-2.34 3.15" actuatorfrcrange="-120 120"/>
          <geom type="mesh" contype="0" conaffinity="0" group="1" density="0" rgba="0.898039 0.917647 0.929412 1" mesh="right_front_Link2"/>
          <geom size="0.023 0.023 0.07" pos="-0.025 -0.003 -0.12" type="box" rgba="0.898039 0.917647 0.929412 1"/>
          <geom size="0.0085 0.025 0.03" pos="-0.022 0 -0.275" quat="0.930508 0 -0.366273 0" type="box" rgba="0.898039 0.917647 0.929412 1"/>
          <body name="FR_calf" pos="0 0 -0.275">
            <inertial pos="0.003855 -0.017411 -0.232224" quat="0.637245 -0.0146461 0.0520319 0.768763" mass="1.75" diaginertia="0.0147385 0.0144011 0.0013464"/>
            <joint name="FR_calf_joint" pos="0 0 0" axis="0 1 0" range="-2.77 -0.54" actuatorfrcrange="-180 180"/>
            <geom type="mesh" contype="0" conaffinity="0" group="1" density="0" rgba="0.792157 0.819608 0.933333 1" mesh="right_front_Link3"/>
            <geom size="0.05 0.015" pos="0 0 -0.275" quat="0.707035 0.707179 0 0" type="cylinder" rgba="0.792157 0.819608 0.933333 1"/>
            <geom size="0.011 0.015 0.05" pos="0.02 0 -0.08" quat="0.992809 0 -0.119712 0" type="box" rgba="0.792157 0.819608 0.933333 1"/>
            <geom size="0.011 0.015 0.04" pos="0.033 0 -0.17" quat="0.999888 0 -0.0149994 0" type="box" rgba="0.792157 0.819608 0.933333 1"/>
            <geom size="0.014 0.02 0.02" pos="0.027 0 -0.23" quat="0.995004 0 0.0998334 0" type="box" rgba="0.792157 0.819608 0.933333 1"/>
            <body name="FR_wheel" pos="0 0 -0.275">
              <inertial pos="0 -0.05108 0" quat="0.707107 0 0 0.707107" mass="0.982" diaginertia="0.00458159 0.00243576 0.00243576"/>
              <joint name="FR_wheel_joint" pos="0 0 0" axis="0 1 0" range="-inf inf" actuatorfrcrange="-24.5 24.5"/>
              <geom type="mesh" contype="0" conaffinity="0" group="1" density="0" rgba="0.792157 0.819608 0.933333 1" mesh="right_front_Link4"/>
              <geom size="0.035" pos="0.0 -0.05 -0.1" contype="0" conaffinity="0" group="1" density="0" rgba="1 0 0 1"/>
              <geom type="mesh" rgba="1 0 0 1" mesh="right_front_Link4"/>
              <body name="right_hand" pos="0.0 -0.05 -0.1">
                <geom type="sphere" size="0.035" contype="0" conaffinity="0" group="1" density="0" rgba="0.6 0.6 0.6 0.0"/>
              </body>
            </body>
          </body>
        </body>
      </body>
      <body name="RR_hip" pos="-0.25944 -0.075113 0">
        <inertial pos="0.00327 0.01622 -3.7e-05" quat="0.616206 0.585144 0.36648 0.378931" mass="1.62" diaginertia="0.00167769 0.00163476 0.00141225"/>
        <joint name="RR_hip_joint" pos="0 0 0" axis="1 0 0" range="-1.01 1.01" actuatorfrcrange="-120 120"/>
        <geom type="mesh" contype="0" conaffinity="0" group="1" density="0" rgba="0.898039 0.917647 0.929412 1" mesh="right_hind_Link1"/>
        <geom size="0.046 0.06" pos="0 -0.085 0" quat="0.707035 0.707179 0 0" type="cylinder" rgba="0.898039 0.917647 0.929412 1"/>
        <geom size="0.045 0.03" pos="0 0.01 0" quat="0.707035 0.707179 0 0" type="cylinder" rgba="0.898039 0.917647 0.929412 1"/>
        <body name="RR_thigh" pos="0 -0.12779 0">
          <inertial pos="-0.003256 0.031125 -0.053921" quat="0.993054 -0.113587 0.0234158 -0.0198545" mass="3.077" diaginertia="0.029323 0.028038 0.00383842"/>
          <joint name="RR_thigh_joint" pos="0 0 0" axis="0 1 0" range="-1.56 3.94" actuatorfrcrange="-120 120"/>
          <geom type="mesh" contype="0" conaffinity="0" group="1" density="0" rgba="0.898039 0.917647 0.929412 1" mesh="right_hind_Link2"/>
          <geom size="0.023 0.023 0.07" pos="-0.025 -0.003 -0.12" type="box" rgba="0.898039 0.917647 0.929412 1"/>
          <geom size="0.0085 0.025 0.03" pos="-0.022 0 -0.275" quat="0.930508 0 -0.366273 0" type="box" rgba="0.898039 0.917647 0.929412 1"/>
          <body name="RR_calf" pos="0 0 -0.275">
            <inertial pos="0.003855 -0.017411 -0.232224" quat="0.637245 -0.0146461 0.0520319 0.768763" mass="1.75" diaginertia="0.0147385 0.0144011 0.0013464"/>
            <joint name="RR_calf_joint" pos="0 0 0" axis="0 1 0" range="-2.77 -0.54" actuatorfrcrange="-180 180"/>
            <geom type="mesh" contype="0" conaffinity="0" group="1" density="0" rgba="0.792157 0.819608 0.933333 1" mesh="right_hind_Link3"/>
            <geom size="0.05 0.015" pos="0 0 -0.275" quat="0.707035 0.707179 0 0" type="cylinder" rgba="0.792157 0.819608 0.933333 1"/>
            <geom size="0.011 0.015 0.05" pos="0.02 0 -0.08" quat="0.992809 0 -0.119712 0" type="box" rgba="0.792157 0.819608 0.933333 1"/>
            <geom size="0.011 0.015 0.04" pos="0.033 0 -0.17" quat="0.999888 0 -0.0149994 0" type="box" rgba="0.792157 0.819608 0.933333 1"/>
            <geom size="0.014 0.02 0.02" pos="0.027 0 -0.23" quat="0.995004 0 0.0998334 0" type="box" rgba="0.792157 0.819608 0.933333 1"/>
            <body name="RR_wheel" pos="0 0 -0.275">
              <inertial pos="0 -0.05108 0" quat="0.707107 0 0 0.707107" mass="0.982" diaginertia="0.00458159 0.00243576 0.00243576"/>
              <joint name="RR_wheel_joint" pos="0 0 0" axis="0 1 0" range="-inf inf" actuatorfrcrange="-24.5 24.5"/>
              <geom type="mesh" contype="0" conaffinity="0" group="1" density="0" rgba="0.792157 0.819608 0.933333 1" mesh="right_hind_Link4"/>
              <geom size="0.035" pos="0.0 -0.05 -0.1" contype="0" conaffinity="0" group="1" density="0" rgba="1 0 0 0.0"/>
              <geom type="mesh" rgba="1 0 0 1" mesh="right_hind_Link4"/>
              <body name="right_foot" pos="0.0 -0.05 -0.1">
                <geom type="sphere" size="0.035" contype="0" conaffinity="0" group="1" density="0" rgba="0.6 0.6 0.6 0.0"/>
                <body name="right_foot_end_link" pos="0.0 0 0.0">
                  <geom type="sphere" size="0.01" contype="0" conaffinity="0" group="1" density="0" rgba="1 0 0 0"/>
                </body>
                <body name="right_toe_link" pos="0.0 0 0.0">
                  <geom type="sphere" size="0.01" contype="0" conaffinity="0" group="1" density="0" rgba="1 0 0 0"/>
                </body>
              </body>
            </body>
          </body>
        </body>
      </body>
    </body>
  </worldbody>

  <actuator>
    <motor ctrlrange="-120 120"  name="FR_hip_joint" joint="FR_hip_joint"/>
    <motor ctrlrange="-120 120"  name="FR_thigh_joint" joint="FR_thigh_joint"/>
    <motor ctrlrange="-180 180"  name="FR_calf_joint" joint="FR_calf_joint"/>
    <motor ctrlrange="-120 120"  name="FL_hip_joint" joint="FL_hip_joint"/>
    <motor ctrlrange="-120 120"  name="FL_thigh_joint" joint="FL_thigh_joint"/>
    <motor ctrlrange="-180 180" name="FL_calf_joint" joint="FL_calf_joint"/>
    <motor ctrlrange="-120 120"  name="RR_hip_joint" joint="RR_hip_joint"/>
    <motor ctrlrange="-120 120"  name="RR_thigh_joint" joint="RR_thigh_joint"/>
    <motor ctrlrange="-180 180" name="RR_calf_joint" joint="RR_calf_joint"/>
    <motor ctrlrange="-120 120"  name="RL_hip_joint" joint="RL_hip_joint"/>
    <motor ctrlrange="-120 120"  name="RL_thigh_joint" joint="RL_thigh_joint"/>
    <motor ctrlrange="-180 180" name="RL_calf_joint" joint="RL_calf_joint"/>
  </actuator>

  <sensor>
    <jointpos name="FR_hip_pos" joint="FR_hip_joint" />
    <jointpos name="FR_thigh_pos" joint="FR_thigh_joint" />
    <jointpos name="FR_calf_pos" joint="FR_calf_joint" />
    <jointpos name="FL_hip_pos" joint="FL_hip_joint" />
    <jointpos name="FL_thigh_pos" joint="FL_thigh_joint" />
    <jointpos name="FL_calf_pos" joint="FL_calf_joint" />
    <jointpos name="RR_hip_pos" joint="RR_hip_joint" />
    <jointpos name="RR_thigh_pos" joint="RR_thigh_joint" />
    <jointpos name="RR_calf_pos" joint="RR_calf_joint" />
    <jointpos name="RL_hip_pos" joint="RL_hip_joint" />
    <jointpos name="RL_thigh_pos" joint="RL_thigh_joint" />
    <jointpos name="RL_calf_pos" joint="RL_calf_joint" />

    <jointvel name="FR_hip_vel" joint="FR_hip_joint" />
    <jointvel name="FR_thigh_vel" joint="FR_thigh_joint" />
    <jointvel name="FR_calf_vel" joint="FR_calf_joint" />
    <jointvel name="FL_hip_vel" joint="FL_hip_joint" />
    <jointvel name="FL_thigh_vel" joint="FL_thigh_joint" />
    <jointvel name="FL_calf_vel" joint="FL_calf_joint" />
    <jointvel name="RR_hip_vel" joint="RR_hip_joint" />
    <jointvel name="RR_thigh_vel" joint="RR_thigh_joint" />
    <jointvel name="RR_calf_vel" joint="RR_calf_joint" />
    <jointvel name="RL_hip_vel" joint="RL_hip_joint" />
    <jointvel name="RL_thigh_vel" joint="RL_thigh_joint" />
    <jointvel name="RL_calf_vel" joint="RL_calf_joint" />
    <jointvel name="FR_wheel_vel" joint="FR_wheel_joint" />
    <jointvel name="FL_wheel_vel" joint="FL_wheel_joint" />
    <jointvel name="RR_wheel_vel" joint="RR_wheel_joint" />
    <jointvel name="RL_wheel_vel" joint="RL_wheel_joint" />


    <jointactuatorfrc name="FR_hip_torque" joint="FR_hip_joint" noise="0.01" />
    <jointactuatorfrc name="FR_thigh_torque" joint="FR_thigh_joint" noise="0.01" />
    <jointactuatorfrc name="FR_calf_torque" joint="FR_calf_joint" noise="0.01" />
    <jointactuatorfrc name="FL_hip_torque" joint="FL_hip_joint" noise="0.01" />
    <jointactuatorfrc name="FL_thigh_torque" joint="FL_thigh_joint" noise="0.01" />
    <jointactuatorfrc name="FL_calf_torque" joint="FL_calf_joint" noise="0.01" />
    <jointactuatorfrc name="RR_hip_torque" joint="RR_hip_joint" noise="0.01" />
    <jointactuatorfrc name="RR_thigh_torque" joint="RR_thigh_joint" noise="0.01" />
    <jointactuatorfrc name="RR_calf_torque" joint="RR_calf_joint" noise="0.01" />
    <jointactuatorfrc name="RL_hip_torque" joint="RL_hip_joint" noise="0.01" />
    <jointactuatorfrc name="RL_thigh_torque" joint="RL_thigh_joint" noise="0.01" />
    <jointactuatorfrc name="RL_calf_torque" joint="RL_calf_joint" noise="0.01" />
    <jointactuatorfrc name="FR_wheel_torque" joint="FR_wheel_joint" noise="0.01" />
    <jointactuatorfrc name="FL_wheel_torque" joint="FL_wheel_joint" noise="0.01" />
    <jointactuatorfrc name="RR_wheel_torque" joint="RR_wheel_joint" noise="0.01" />
    <jointactuatorfrc name="RL_wheel_torque" joint="RL_wheel_joint" noise="0.01" />

    <!-- <framequat name="imu_quat" objtype="site" objname="imu" noise="0.01" /> -->
    <!-- <gyro name="imu_gyro" site="imu" noise="0.01" /> -->
    <!-- <accelerometer name="imu_acc" site="imu" noise="0.01" /> -->
    
    <!-- <framepos name="frame_pos" objtype="site" objname="imu" /> -->
    <!-- <framelinvel name="frame_vel" objtype="site" objname="imu" /> -->
  </sensor>

  <!-- setup scene -->
  <!-- <statistic center="1.0 0.7 1.0" extent="0.8"/>
  <visual>
    <headlight diffuse="0.6 0.6 0.6" ambient="0.1 0.1 0.1" specular="0.9 0.9 0.9"/>
    <rgba haze="0.15 0.25 0.35 1"/>
    <global azimuth="-140" elevation="-20"/>
  </visual>
  <asset>
    <texture type="skybox" builtin="flat" rgb1="0 0 0" rgb2="0 0 0" width="512" height="3072"/>
    <texture type="2d" name="groundplane" builtin="checker" mark="edge" rgb1="0.2 0.3 0.4" rgb2="0.1 0.2 0.3" markrgb="0.8 0.8 0.8" width="300" height="300"/>
    <material name="groundplane" texture="groundplane" texuniform="true" texrepeat="5 5" reflectance="0.2"/>
  </asset>
  <worldbody>
    <light pos="1 0 3.5" dir="0 0 -1" directional="true"/>
    <geom name="floor" size="0 0 0.05" type="plane" material="groundplane" friction="0.75 0.02 0.001"/>
  </worldbody> -->


</mujoco>
