<?xml version="1.0" encoding="utf-8"?>
<!-- This URDF was automatically created by SolidWorks to URDF Exporter! Originally created by Stephen Brawner (brawner@gmail.com) 
     Commit Version: 1.6.0-4-g7f85cfe  Build Version: 1.6.7995.38578
     For more information, please see http://wiki.ros.org/sw_urdf_exporter -->
<robot
  name="X2-0807urdf">
  <!-- <mujoco>
    <compiler meshdir="meshes" discardvisual="false"/>
  </mujoco>
  <link name="world"></link>
  <joint name="floating_base_joint" type="floating">
    <parent link="world"/>
    <child link="base_link"/>
  </joint> -->
  <link
    name="base_link">
    <inertial>
      <origin
        xyz="6.982591E-03 -0.712858E-03 12.889523E-03"
        rpy="0 0 0" />
      <mass
        value="19.651" />
      <inertia
        ixx="141775.328248061E-06"
        ixy="400.505020171E-06"
        ixz="-6996.487718114E-06"
        iyy="407724.601564754E-06"
        iyz="-361.858857563E-06"
        izz="472247.985516800E-06" />
    </inertial>
    <visual>
      <origin
        xyz="0 0 0"
        rpy="0 0 0" />
      <geometry>
        <mesh
          filename="./meshes/base_link.STL" />
      </geometry>
      <material
        name="">
        <color
          rgba="0.792156862745098 0.819607843137255 0.933333333333333 1" />
      </material>
    </visual>
    <collision>
      <origin xyz="0 0 0.01" rpy="0 0 0" />
      <geometry>
        <box size="0.24 0.28 0.16" />
      </geometry>
    </collision>
  </link>

  <!-- 前保险杠link -->
  <link name="front_bumper">
    <inertial>
      <origin xyz="0 0 0" rpy="0 0 0"/>
      <mass value="0.01"/>
      <inertia ixx="0.001" ixy="0" ixz="0" iyy="0.001" iyz="0" izz="0.001"/>
    </inertial>
    <!-- <visual>
      <origin xyz="0 0 0" rpy="0 0 0"/>
      <geometry>
        <box size="0.05 0.1 0.01"/>
      </geometry>
      <material name="">
        <color rgba="0.5 0.5 0.5 1"/>
      </material>
    </visual> -->
    <collision>
      <origin xyz="0.365 0 0.1" rpy="0 -0.7 0"/>
      <geometry>
        <box size="0.05 0.1 0.01"/>
      </geometry>
    </collision>
    <collision>
      <origin xyz="0.345 0 0.08" rpy="0 -0.0 0"/>
      <geometry>
        <sphere radius="0.04"/>
      </geometry>
    </collision>
    <collision>
      <origin xyz="0.25 0 0.09" rpy="0 -0.0 0"/>
      <geometry>
        <sphere radius="0.04"/>
      </geometry>
    </collision>
  </link>
  
  <!-- 前保险杠关节 -->
  <joint name="front_bumper_joint" type="fixed" dont_collapse="true">
    <origin xyz="0.0 0 0" rpy="0 0 0"/>
    <parent link="base_link"/>
    <child link="front_bumper"/>
  </joint>
  
  <!-- 后保险杠link -->
  <link name="rear_bumper">
    <inertial>
      <origin xyz="0 0 0" rpy="0 0 0"/>
      <mass value="0.01"/>
      <inertia ixx="0.001" ixy="0" ixz="0" iyy="0.001" iyz="0" izz="0.001"/>
    </inertial>

    <collision>
    <origin xyz="-0.302 0 0.112" rpy="0 0.7 0"/>
      <geometry>
        <box size="0.05 0.1 0.01"/>
      </geometry>
    </collision>
    <collision>
      <origin xyz="-0.285 0 0.08" rpy="0 -0.0 0"/>
      <geometry>
        <sphere radius="0.04"/>
      </geometry>
    </collision>
    <collision>
      <origin xyz="-0.19 0 0.09" rpy="0 -0.0 0"/>
      <geometry>
        <sphere radius="0.04"/>
      </geometry>
    </collision>
  </link>
  
  <!-- 后保险杠关节 -->
  <joint name="rear_bumper_joint"  type="fixed" dont_collapse="true">
    <origin xyz="0.0 0 0" rpy="0 0 0"/>
    <parent link="base_link"/>
    <child link="rear_bumper"/>
  </joint>

  <link
    name="FL_hip">
    <inertial>
      <origin
        xyz="-2.408E-03 -16.220E-03 0.239E-03"
        rpy="0 0 0" />
      <mass
        value="1.620" />
      <inertia
        ixx="1476.261E-06"
        ixy="53.160E-06"
        ixz="-7.425E-06"
        iyy="1633.309E-06"
        iyz="-21.032E-06"
        izz="1630.804E-06" />
    </inertial>
    <visual>
      <origin
        xyz="0 0 0"
        rpy="0 0 0" />
      <geometry>
        <mesh
          filename="./meshes/left_front_Link1.STL" />
      </geometry>
      <material
        name="">
        <color
          rgba="0.898039215686275 0.917647058823529 0.929411764705882 1" />
      </material>
    </visual>
    <collision>
      <origin xyz="0.0 0.085 0" rpy="1.571 0 0" />
      <geometry>
        <cylinder radius="0.046" length="0.12" />
      </geometry>
    </collision>
    <collision>
      <origin xyz="0.0 -0.01 0" rpy="1.571 0 0" />
      <geometry>
        <cylinder radius="0.045" length="0.06" />
      </geometry>
    </collision>
  </link>
  <joint
    name="FL_hip_joint"
    type="revolute">
    <origin
      xyz="0.25944 0.075113 0"
      rpy="0 0 0" />
    <parent
      link="base_link" />
    <child
      link="FL_hip" />
    <axis
      xyz="1 0 0" />
    <limit
      lower="-1.01"
      upper="1.01"
      effort="120.0"
      velocity="22.0" />
  </joint>
  
  <link
    name="FL_thigh">
    <inertial>
      <origin
        xyz="-3.268E-03 -31.110E-03 -53.896E-03"
        rpy="0 0 0" />
      <mass
        value="3.079" />
      <inertia
        ixx="29271.794E-06"
        ixy="337.285E-06"
        ixz="-1251.409E-06"
        iyy="26828.777E-06"
        iyz="5283.783E-06"
        izz="5121.720E-06" />
    </inertial>
    <visual>
      <origin
        xyz="0 0 0"
        rpy="0 0 0" />
      <geometry>
        <mesh
          filename="./meshes/left_front_Link2.STL" />
      </geometry>
      <material
        name="">
        <color
          rgba="0.898039215686275 0.917647058823529 0.929411764705882 1" />
      </material>
    </visual>
    <collision>
      <origin xyz="-0.025 -0.003 -0.12" rpy="0 0.0 0" />
      <geometry>
        <box size="0.046 0.046 0.14" />
      </geometry>
    </collision>
    <collision>
      <origin xyz="-0.022 0.00 -0.275" rpy="0 -0.75 0" />
      <geometry>
        <box size="0.017 0.05 0.06" />
      </geometry>
    </collision>
  </link>
  <joint
    name="FL_thigh_joint"
    type="revolute">
    <origin
      xyz="0 0.12779 0"
      rpy="0 0 0" />
    <parent
      link="FL_hip" />
    <child
      link="FL_thigh" />
    <axis
      xyz="0 1 0" />
    <limit
      lower="-2.34"
      upper="3.15"
      effort="120.0"
      velocity="22.0" />
  </joint>
  <link
    name="FL_calf">
    <inertial>
      <origin
        xyz="4.018E-03 17.411E-03 -232.283E-03"
        rpy="0 0 0" />
      <mass
        value="1.751" />
      <inertia
        ixx="14397.534E-06"
        ixy="124.726E-06"
        ixz="-550.242E-06"
        iyy="14603.730E-06"
        iyz="1307.539E-06"
        izz="1498.341E-06" />
    </inertial>
    <visual>
      <origin
        xyz="0 0 0"
        rpy="0 0 0" />
      <geometry>
        <mesh
          filename="./meshes/left_front_Link3.STL" />
      </geometry>
      <material
        name="">
        <color
          rgba="0.792156862745098 0.819607843137255 0.933333333333333 1" />
      </material>
    </visual>
    <collision>
      <origin xyz="0.0 0.0 -0.275" rpy="1.571 0 0" />
      <geometry>
        <cylinder radius="0.05" length="0.03" />
      </geometry>
    </collision>
    <collision>
      <origin xyz="0.02 -0.00 -0.08" rpy="0 -0.24 0" />
      <geometry>
        <box size="0.022 0.03 0.1" />
      </geometry>
    </collision>
    <collision>
      <origin xyz="0.033 -0.00 -0.17" rpy="0 -0.03 0" />
      <geometry>
        <box size="0.022 0.03 0.08" />
      </geometry>
    </collision>
    <collision>
      <origin xyz="0.027 -0.00 -0.23" rpy="0 0.2 0" />
      <geometry>
        <box size="0.028 0.04 0.04" />
      </geometry>
    </collision>
  </link>
  <joint
    name="FL_calf_joint"
    type="revolute">
    <origin
      xyz="0 0 -0.275"
      rpy="0 0 0" />
    <parent
      link="FL_thigh" />
    <child
      link="FL_calf" />
    <axis
      xyz="0 1 0" />
    <limit
      lower="-2.77"
      upper="-0.54"
      effort="180.0"
      velocity="14.6667" />
  </joint>
  <link
    name="FL_wheel">
    <inertial>
      <origin
        xyz="0E-03 51.080E-03 0E-03"
        rpy="0 0 0" />
      <mass
        value="0.982" />
      <inertia
        ixx="2435.762E-06"
        ixy="0E-06"
        ixz="0E-06"
        iyy="4581.589E-06"
        iyz="0E-06"
        izz="2435.762E-06" />
    </inertial>
    <visual>
      <origin
        xyz="0 0 0"
        rpy="0 0 0" />
      <geometry>
        <mesh
          filename="./meshes/left_front_Link4.STL" />
      </geometry>
      <material
        name="">
        <color
          rgba="0.792156862745098 0.819607843137255 0.933333333333333 1" />
      </material>
    </visual>
    <visual>
      <origin
        xyz="0.1 0.05 0"
        rpy="0 0 0" />
      <geometry>
        <sphere
          radius="0.05" />
      </geometry>
      <material
        name="">
        <color
          rgba="1 0 0 1" />
      </material>
    </visual>
    <collision>
      <origin
        xyz="0 0 0"
        rpy="0 0 0" />
      <geometry>
        <mesh
          filename="./meshes/left_front_Link4.STL" />
      </geometry>
    </collision>
  </link>
  <joint
    name="FL_wheel_joint"
    type="revolute">
    <origin
      xyz="0 0 -0.275"
      rpy="0 0 0" />
    <parent
      link="FL_calf" />
    <child
      link="FL_wheel" />
    <axis
      xyz="0 1 0" />
    <limit
      effort="24.5"
      velocity="114.4"
      lower="-inf" 
      upper="inf" />
  </joint>

  <link
    name="RL_hip">
    <inertial>
      <origin
        xyz="3.270E-03 -16.220E-03 -0.097E-03"
        rpy="0 0 0" />
      <mass
        value="1.620" />
      <inertia
        ixx="1468.092E-06"
        ixy="-105.396E-06"
        ixz="-7.294E-06"
        iyy="1625.457E-06"
        iyz="-0.444E-06"
        izz="1631.122E-06" />
    </inertial>
    <visual>
      <origin
        xyz="0 0 0"
        rpy="0 0 0" />
      <geometry>
        <mesh
          filename="./meshes/left_hind_Link1.STL" />
      </geometry>
      <material
        name="">
        <color
          rgba="0.898039215686275 0.917647058823529 0.929411764705882 1" />
      </material>
    </visual>
  <collision>
      <origin xyz="0.0 0.085 0" rpy="1.571 0 0" />
      <geometry>
        <cylinder radius="0.046" length="0.12" />
      </geometry>
    </collision>
    <collision>
      <origin xyz="0.0 -0.01 0" rpy="1.571 0 0" />
      <geometry>
        <cylinder radius="0.045" length="0.06" />
      </geometry>
    </collision>
  </link>
  <joint
    name="RL_hip_joint"
    type="revolute">
    <origin
      xyz="-0.25944 0.075113 0"
      rpy="0 0 0" />
    <parent
      link="base_link" />
    <child
      link="RL_hip" />
    <axis
      xyz="1 0 0" />
    <limit
      lower="-1.01"
      upper="1.01"
      effort="120.0"
      velocity="22.0" />
  </joint>
  <link
    name="RL_thigh">
    <inertial>
      <origin
        xyz="-3.268E-03 -31.110E-03 -53.896E-03"
        rpy="0 0 0" />
      <mass
        value="3.079" />
      <inertia
        ixx="29271.794E-06"
        ixy="337.285E-06"
        ixz="-1251.409E-06"
        iyy="26828.777E-06"
        iyz="5283.783E-06"
        izz="5121.720E-06" />
    </inertial>
    <visual>
      <origin
        xyz="0 0 0"
        rpy="0 0 0" />
      <geometry>
        <mesh
          filename="./meshes/left_hind_Link2.STL" />
      </geometry>
      <material
        name="">
        <color
          rgba="0.898039215686275 0.917647058823529 0.929411764705882 1" />
      </material>
    </visual>
    <collision>
      <origin xyz="-0.025 -0.003 -0.12" rpy="0 0.0 0" />
      <geometry>
        <box size="0.046 0.046 0.14" />
      </geometry>
    </collision>
    <collision>
      <origin xyz="-0.022 0.00 -0.275" rpy="0 -0.75 0" />
      <geometry>
        <box size="0.017 0.05 0.06" />
      </geometry>
    </collision>
  </link>
  <joint
    name="RL_thigh_joint"
    type="revolute">
    <origin
      xyz="0 0.12779 0"
      rpy="0 0 0" />
    <parent
      link="RL_hip" />
    <child
      link="RL_thigh" />
    <axis
      xyz="0 1 0" />
    <limit
      lower="-1.56"
      upper="3.94"
      effort="120.0"
      velocity="22.0" />
  </joint>
  <link
    name="RL_calf">
    <inertial>
      <origin
        xyz="4.018E-03 17.411E-03 -232.283E-03"
        rpy="0 0 0" />
      <mass
        value="1.751" />
      <inertia
        ixx="14397.534E-06"
        ixy="124.726E-06"
        ixz="-550.242E-06"
        iyy="14603.730E-06"
        iyz="1307.539E-06"
        izz="1498.341E-06" />
    </inertial>
    <visual>
      <origin
        xyz="0 0 0"
        rpy="0 0 0" />
      <geometry>
        <mesh
          filename="./meshes/left_hind_Link3.STL" />
      </geometry>
      <material
        name="">
        <color
          rgba="0.792156862745098 0.819607843137255 0.933333333333333 1" />
      </material>
    </visual>
    <collision>
      <origin xyz="0.0 0.0 -0.275" rpy="1.571 0 0" />
      <geometry>
        <cylinder radius="0.05" length="0.03" />
      </geometry>
    </collision>
    <collision>
      <origin xyz="0.02 -0.00 -0.08" rpy="0 -0.24 0" />
      <geometry>
        <box size="0.022 0.03 0.1" />
      </geometry>
    </collision>
    <collision>
      <origin xyz="0.033 -0.00 -0.17" rpy="0 -0.03 0" />
      <geometry>
        <box size="0.022 0.03 0.08" />
      </geometry>
    </collision>
    <collision>
      <origin xyz="0.027 -0.00 -0.23" rpy="0 0.2 0" />
      <geometry>
        <box size="0.028 0.04 0.04" />
      </geometry>
    </collision>
  </link>
  <joint
    name="RL_calf_joint"
    type="revolute">
    <origin
      xyz="0 0 -0.275"
      rpy="0 0 0" />
    <parent
      link="RL_thigh" />
    <child
      link="RL_calf" />
    <axis
      xyz="0 1 0" />
    <limit
      lower="-2.77"
      upper="-0.54"
      effort="180.0"
      velocity="14.6667" />
  </joint>
  <link
    name="RL_wheel">
    <inertial>
      <origin
        xyz="0E-03 51.080E-03 0E-03"
        rpy="0 0 0" />
      <mass
        value="0.982" />
      <inertia
        ixx="2435.762E-06"
        ixy="0E-06"
        ixz="0E-06"
        iyy="4581.589E-06"
        iyz="0E-06"
        izz="2435.762E-06" />
    </inertial>
    <visual>
      <origin
        xyz="0 0 0"
        rpy="0 0 0" />
      <geometry>
        <mesh
          filename="./meshes/left_hind_Link4.STL" />
      </geometry>
      <material
        name="">
        <color
          rgba="0.792156862745098 0.819607843137255 0.933333333333333 1" />
      </material>
    </visual>
    <visual>
      <origin
        xyz="0.1 0.05 0"
        rpy="0 0 0" />
      <geometry>
        <sphere
          radius="0.05" />
      </geometry>
      <material
        name="">
        <color
          rgba="1 0 0 1" />
      </material>
    </visual>
    <collision>
      <origin
        xyz="0 0 0"
        rpy="0 0 0" />
      <geometry>
        <mesh
          filename="./meshes/left_hind_Link4.STL" />
      </geometry>
    </collision>
  </link>
  <joint
    name="RL_wheel_joint"
    type="revolute">
    <origin
      xyz="0 0 -0.275"
      rpy="0 0 0" />
    <parent
      link="RL_calf" />
    <child
      link="RL_wheel" />
    <axis
      xyz="0 1 0" />
    <limit
      effort="24.5"
      velocity="114.4"
      lower="-inf" 
      upper="inf" />
  </joint>
  <link
    name="FR_hip">
    <inertial>
      <origin
        xyz="-2.465E-03 16.220E-03 0.318E-03"
        rpy="0 0 0" />
      <mass
        value="1.620" />
      <inertia
        ixx="1483.677E-06"
        ixy="-56.616E-06"
        ixz="-5.890E-06"
        iyy="1632.784E-06"
        iyz="25.536E-06"
        izz="1622.864E-06" />
    </inertial>
    <visual>
      <origin
        xyz="0 0 0"
        rpy="0 0 0" />
      <geometry>
        <mesh
          filename="./meshes/right_front_Link1.STL" />
      </geometry>
      <material
        name="">
        <color
          rgba="0.898039215686275 0.917647058823529 0.929411764705882 1" />
      </material>
    </visual>
    <collision>
      <origin xyz="0.0 -0.085 0" rpy="1.571 0 0" />
      <geometry>
        <cylinder radius="0.046" length="0.12" />
      </geometry>
    </collision>
    <collision>
      <origin xyz="0.0 0.01 0" rpy="1.571 0 0" />
      <geometry>
        <cylinder radius="0.045" length="0.06" />
      </geometry>
    </collision>
  </link>
  <joint
    name="FR_hip_joint"
    type="revolute">
    <origin
      xyz="0.25944 -0.075113 0"
      rpy="0 0 0" />
    <parent
      link="base_link" />
    <child
      link="FR_hip" />
    <axis
      xyz="1 0 0" />
    <limit
      lower="-1.01"
      upper="1.01"
      effort="120.0"
      velocity="22.0" />
  </joint>
  <link
    name="FR_thigh">
    <inertial>
      <origin
        xyz="-3.256E-03 31.125E-03 -53.921E-03"
        rpy="0 0 0" />
      <mass
        value="3.077" />
      <inertia
        ixx="29255.209E-06"
        ixy="-334.771E-06"
        ixz="-1255.239E-06"
        iyy="26819.094E-06"
        iyz="-5288.175E-06"
        izz="5125.147E-06" />
    </inertial>
    <visual>
      <origin
        xyz="0 0 0"
        rpy="0 0 0" />
      <geometry>
        <mesh
          filename="./meshes/right_front_Link2.STL" />
      </geometry>
      <material
        name="">
        <color
          rgba="0.898039215686275 0.917647058823529 0.929411764705882 1" />
      </material>
    </visual>
    <collision>
      <origin xyz="-0.025 -0.003 -0.12" rpy="0 0.0 0" />
      <geometry>
        <box size="0.046 0.046 0.14" />
      </geometry>
    </collision>
    <collision>
      <origin xyz="-0.022 0.00 -0.275" rpy="0 -0.75 0" />
      <geometry>
        <box size="0.017 0.05 0.06" />
      </geometry>
    </collision>
  </link>
  <joint
    name="FR_thigh_joint"
    type="revolute">
    <origin
      xyz="0 -0.12779 0"
      rpy="0 0 0" />
    <parent
      link="FR_hip" />
    <child
      link="FR_thigh" />
    <axis
      xyz="0 1 0" />
    <limit
      lower="-2.34"
      upper="3.15"
      effort="120.0"
      velocity="22.0" />
  </joint>
  <link
    name="FR_calf">
    <inertial>
      <origin
        xyz="3.855E-03 -17.411E-03 -232.224E-03"
        rpy="0 0 0" />
      <mass
        value="1.750" />
      <inertia
        ixx="14387.884E-06"
        ixy="-118.281E-06"
        ixz="-562.776E-06"
        iyy="14596.939E-06"
        iyz="-1309.862E-06"
        izz="1501.193E-06" />
    </inertial>
    <visual>
      <origin
        xyz="0 0 0"
        rpy="0 0 0" />
      <geometry>
        <mesh
          filename="./meshes/right_front_Link3.STL" />
      </geometry>
      <material
        name="">
        <color
          rgba="0.792156862745098 0.819607843137255 0.933333333333333 1" />
      </material>
    </visual>
    <collision>
      <origin xyz="0.0 0.0 -0.275" rpy="1.571 0 0" />
      <geometry>
        <cylinder radius="0.05" length="0.03" />
      </geometry>
    </collision>
    <collision>
      <origin xyz="0.02 -0.00 -0.08" rpy="0 -0.24 0" />
      <geometry>
        <box size="0.022 0.03 0.1" />
      </geometry>
    </collision>
    <collision>
      <origin xyz="0.033 -0.00 -0.17" rpy="0 -0.03 0" />
      <geometry>
        <box size="0.022 0.03 0.08" />
      </geometry>
    </collision>
    <collision>
      <origin xyz="0.027 -0.00 -0.23" rpy="0 0.2 0" />
      <geometry>
        <box size="0.028 0.04 0.04" />
      </geometry>
    </collision>
  </link>
  <joint
    name="FR_calf_joint"
    type="revolute">
    <origin
      xyz="0 0 -0.275"
      rpy="0 0 0" />
    <parent
      link="FR_thigh" />
    <child
      link="FR_calf" />
    <axis
      xyz="0 1 0" />
    <limit
      lower="-2.77"
      upper="-0.54"
      effort="180.0"
      velocity="14.6667" />
  </joint>
  <link
    name="FR_wheel">
    <inertial>
      <origin
        xyz="0E-03 -51.080E-03 0E-03"
        rpy="0 0 0" />
      <mass
        value="0.982" />
      <inertia
        ixx="2435.762E-06"
        ixy="0E-06"
        ixz="0E-06"
        iyy="4581.589E-06"
        iyz="0E-06"
        izz="2435.762E-06" />
    </inertial>
    <visual>
      <origin
        xyz="0 0 0"
        rpy="0 0 0" />
      <geometry>
        <mesh
          filename="./meshes/right_front_Link4.STL" />
      </geometry>
      <material
        name="">
        <color
          rgba="0.792156862745098 0.819607843137255 0.933333333333333 1" />
      </material>
    </visual>
    <visual>
      <origin
        xyz="0.1 -0.05 0"
        rpy="0 0 0" />
      <geometry>
        <sphere
          radius="0.05" />
      </geometry>
      <material
        name="">
        <color
          rgba="1 0 0 1" />
      </material>
    </visual>
    <collision>
      <origin
        xyz="0 0 0"
        rpy="0 0 0" />
      <geometry>
        <mesh
          filename="./meshes/right_front_Link4.STL" />
      </geometry>
    </collision>
  </link>
  <joint
    name="FR_wheel_joint"
    type="revolute">
    <origin
      xyz="0 0 -0.275"
      rpy="0 0 0" />
    <parent
      link="FR_calf" />
    <child
      link="FR_wheel" />
    <axis
      xyz="0 1 0" />
    <limit
      effort="24.5"
      velocity="114.4"
      lower="-inf" 
      upper="inf" />
  </joint>
  <link
    name="RR_hip">
    <inertial>
      <origin
        xyz="3.270E-03 16.220E-03 -0.037E-03"
        rpy="0 0 0" />
      <mass
        value="1.620" />
      <inertia
        ixx="1464.949E-06"
        ixy="105.396E-06"
        ixz="-9.437E-06"
        iyy="1625.469E-06"
        iyz="4.282E-06"
        izz="1634.276E-06" />
    </inertial>
    <visual>
      <origin
        xyz="0 0 0"
        rpy="0 0 0" />
      <geometry>
        <mesh
          filename="./meshes/right_hind_Link1.STL" />
      </geometry>
      <material
        name="">
        <color
          rgba="0.898039215686275 0.917647058823529 0.929411764705882 1" />
      </material>
    </visual>
    <collision>
      <origin xyz="0.0 -0.085 0" rpy="1.571 0 0" />
      <geometry>
        <cylinder radius="0.046" length="0.12" />
      </geometry>
    </collision>
    <collision>
      <origin xyz="0.0 0.01 0" rpy="1.571 0 0" />
      <geometry>
        <cylinder radius="0.045" length="0.06" />
      </geometry>
    </collision>
  </link>
  <joint
    name="RR_hip_joint"
    type="revolute">
    <origin
      xyz="-0.25944 -0.075113 0"
      rpy="0 0 0" />
    <parent
      link="base_link" />
    <child
      link="RR_hip" />
    <axis
      xyz="1 0 0" />
    <limit
      lower="-1.01"
      upper="1.01"
      effort="120.0"
      velocity="22.0" />
  </joint>
  <link
    name="RR_thigh">
    <inertial>
      <origin
        xyz="-3.256E-03 31.125E-03 -53.921E-03"
        rpy="0 0 0" />
      <mass
        value="3.077" />
      <inertia
        ixx="29255.209E-06"
        ixy="-334.771E-06"
        ixz="-1255.239E-06"
        iyy="26819.094E-06"
        iyz="-5288.175E-06"
        izz="5125.147E-06" />
    </inertial>
    <visual>
      <origin
        xyz="0 0 0"
        rpy="0 0 0" />
      <geometry>
        <mesh
          filename="./meshes/right_hind_Link2.STL" />
      </geometry>
      <material
        name="">
        <color
          rgba="0.898039215686275 0.917647058823529 0.929411764705882 1" />
      </material>
    </visual>
    <collision>
      <origin xyz="-0.025 -0.003 -0.12" rpy="0 0.0 0" />
      <geometry>
        <box size="0.046 0.046 0.14" />
      </geometry>
    </collision>
    <collision>
      <origin xyz="-0.022 0.00 -0.275" rpy="0 -0.75 0" />
      <geometry>
        <box size="0.017 0.05 0.06" />
      </geometry>
    </collision>
  </link>
  <joint
    name="RR_thigh_joint"
    type="revolute">
    <origin
      xyz="0 -0.12779 0"
      rpy="0 0 0" />
    <parent
      link="RR_hip" />
    <child
      link="RR_thigh" />
    <axis
      xyz="0 1 0" />
    <limit
      lower="-1.56"
      upper="3.94"
      effort="120.0"
      velocity="22.0" />
  </joint>
  <link
    name="RR_calf">
    <inertial>
      <origin
        xyz="3.855E-03 -17.411E-03 -232.224E-03"
        rpy="0 0 0" />
      <mass
        value="1.750" />
      <inertia
        ixx="14387.884E-06"
        ixy="-118.281E-06"
        ixz="-562.776E-06"
        iyy="14596.939E-06"
        iyz="-1309.862E-06"
        izz="1501.193E-06" />
    </inertial>
    <visual>
      <origin
        xyz="0 0 0"
        rpy="0 0 0" />
      <geometry>
        <mesh
          filename="./meshes/right_hind_Link3.STL" />
      </geometry>
      <material
        name="">
        <color
          rgba="0.792156862745098 0.819607843137255 0.933333333333333 1" />
      </material>
    </visual>
    <collision>
      <origin xyz="0.0 0.0 -0.275" rpy="1.571 0 0" />
      <geometry>
        <cylinder radius="0.05" length="0.03" />
      </geometry>
    </collision>
    <collision>
      <origin xyz="0.02 -0.00 -0.08" rpy="0 -0.24 0" />
      <geometry>
        <box size="0.022 0.03 0.1" />
      </geometry>
    </collision>
    <collision>
      <origin xyz="0.033 -0.00 -0.17" rpy="0 -0.03 0" />
      <geometry>
        <box size="0.022 0.03 0.08" />
      </geometry>
    </collision>
    <collision>
      <origin xyz="0.027 -0.00 -0.23" rpy="0 0.2 0" />
      <geometry>
        <box size="0.028 0.04 0.04" />
      </geometry>
    </collision>
  </link>
  <joint
    name="RR_calf_joint"
    type="revolute">
    <origin
      xyz="0 0 -0.275"
      rpy="0 0 0" />
    <parent
      link="RR_thigh" />
    <child
      link="RR_calf" />
    <axis
      xyz="0 1 0" />
    <limit
      lower="-2.77"
      upper="-0.54"
      effort="180.0"
      velocity="14.6667" />
  </joint>
  <link
    name="RR_wheel">
    <inertial>
      <origin
        xyz="0E-03 -51.080E-03 0E-03"
        rpy="0 0 0" />
      <mass
        value="0.982" />
      <inertia
        ixx="2435.762E-06"
        ixy="0E-06"
        ixz="0E-06"
        iyy="4581.589E-06"
        iyz="0E-06"
        izz="2435.762E-06" />
    </inertial>
    <visual>
      <origin
        xyz="0 0 0"
        rpy="0 0 0" />
      <geometry>
        <mesh
          filename="./meshes/right_hind_Link4.STL" />
      </geometry>
      <material
        name="">
        <color
          rgba="0.792156862745098 0.819607843137255 0.933333333333333 1" />
      </material>
    </visual>
    <visual>
      <origin
        xyz="0.1 -0.05 0"
        rpy="0 0 0" />
      <geometry>
        <sphere
          radius="0.05" />
      </geometry>
      <material
        name="">
        <color
          rgba="1 0 0 1" />
      </material>
    </visual>
    <collision>
      <origin
        xyz="0 0 0"
        rpy="0 0 0" />
      <geometry>
        <mesh
          filename="./meshes/right_hind_Link4.STL" />
      </geometry>
    </collision>
  </link>
  <joint
    name="RR_wheel_joint"
    type="revolute">
    <origin
      xyz="0 0 -0.275"
      rpy="0 0 0" />
    <parent
      link="RR_calf" />
    <child
      link="RR_wheel" />
    <axis
      xyz="0 1 0" />
    <limit
      effort="24.5"
      velocity="114.4"
      lower="-inf" 
      upper="inf" />
  </joint>
</robot>
