<mujoco model="R1">
  <compiler angle="radian" meshdir="meshes/"/>

  <statistic meansize="0.144785" extent="1.23314" center="0.025392 2.0634e-05 -0.245975"/>
  <default>
    <joint damping="0.001" armature="0.01" frictionloss="0.1"/>
  </default>
  <option timestep="0.002"/> 
  <option integrator="implicit"/>

  <asset>
    <mesh name="pelvis_link" file="pelvis_link.STL"/>
    <mesh name="left_hip_pitch_link" file="left_hip_pitch_link.STL"/>
    <mesh name="left_hip_roll_link" file="left_hip_roll_link.STL"/>
    <mesh name="left_hip_yaw_link" file="left_hip_yaw_link.STL"/>
    <mesh name="left_knee_link" file="left_knee_link.STL"/>
    <mesh name="left_knee_collision" file="left_knee_collision.STL"/>
    <mesh name="left_ankle_A_link" file="left_ankle_A_link.STL"/>
    <mesh name="left_ankle_A_rod_link" file="left_ankle_A_rod_link.STL"/>
    <mesh name="left_ankle_B_link" file="left_ankle_B_link.STL"/>
    <mesh name="left_ankle_B_rod_link" file="left_ankle_B_rod_link.STL"/>
    <mesh name="left_ankle_pitch_link" file="left_ankle_pitch_link.STL"/>
    <mesh name="left_ankle_roll_link" file="left_ankle_roll_link.STL"/>
    <mesh name="left_ankle_constraint_A_link" file="left_ankle_constraint_A_link.STL"/>
    <mesh name="left_ankle_constraint_B_link" file="left_ankle_constraint_B_link.STL"/>
    <mesh name="right_hip_pitch_link" file="right_hip_pitch_link.STL"/>
    <mesh name="right_hip_roll_link" file="right_hip_roll_link.STL"/>
    <mesh name="right_hip_yaw_link" file="right_hip_yaw_link.STL"/>
    <mesh name="right_knee_link" file="right_knee_link.STL"/>
    <mesh name="right_knee_collision" file="right_knee_collision.STL"/>
    <mesh name="right_ankle_A_link" file="right_ankle_A_link.STL"/>
    <mesh name="right_ankle_A_rod_link" file="right_ankle_A_rod_link.STL"/>
    <mesh name="right_ankle_B_link" file="right_ankle_B_link.STL"/>
    <mesh name="right_ankle_B_rod_link" file="right_ankle_B_rod_link.STL"/>
    <mesh name="right_ankle_pitch_link" file="right_ankle_pitch_link.STL"/>
    <mesh name="right_ankle_roll_link" file="right_ankle_roll_link.STL"/>
    <mesh name="right_ankle_constraint_A_link" file="right_ankle_constraint_A_link.STL"/>
    <mesh name="right_ankle_constraint_B_link" file="right_ankle_constraint_B_link.STL"/>
    <mesh name="imu_in_pelvis_link" file="imu_in_pelvis_link.STL"/>
    <mesh name="waist_roll_link" file="waist_roll_link.STL"/>
    <mesh name="waist_yaw_link" file="waist_yaw_link.STL"/>
    <mesh name="left_shoulder_pitch_link" file="left_shoulder_pitch_link.STL"/>
    <mesh name="left_shoulder_roll_link" file="left_shoulder_roll_link.STL"/>
    <mesh name="left_shoulder_yaw_link" file="left_shoulder_yaw_link.STL"/>
    <mesh name="left_elbow_link" file="left_elbow_link.STL"/>
    <mesh name="left_wrist_roll_link" file="left_wrist_roll_link.STL"/>
    <mesh name="right_shoulder_pitch_link" file="right_shoulder_pitch_link.STL"/>
    <mesh name="right_shoulder_roll_link" file="right_shoulder_roll_link.STL"/>
    <mesh name="right_shoulder_yaw_link" file="right_shoulder_yaw_link.STL"/>
    <mesh name="right_elbow_link" file="right_elbow_link.STL"/>
    <mesh name="right_wrist_roll_link" file="right_wrist_roll_link.STL"/>
    <mesh name="head_pitch_link" file="head_pitch_link.STL"/>
    <mesh name="head_yaw_link" file="head_yaw_link.STL"/>
  </asset>

  <worldbody>
    <body name="pelvis_link" pos="0.0 0.0 0.78">
      <inertial pos="0.0269881 0.000184581 -0.0704106" quat="0.703476 0.707138 -0.0498219 0.0509351" mass="2.25001" diaginertia="0.00646721 0.00620017 0.00381749"/>
      <joint name="floating_base_joint" type="free"/>
      <geom type="mesh" contype="0" conaffinity="0" group="1" density="0" rgba="0.7 0.7 0.7 1" mesh="pelvis_link"/>
      <geom type="mesh" rgba="0.7 0.7 0.7 1" mesh="pelvis_link"/>
      <geom pos="0.0762025 2.19914e-05 -0.0884315" quat="1 0 0 0" type="mesh" contype="0" conaffinity="0" group="1" density="0" rgba="0.7 0.7 0.7 1" mesh="imu_in_pelvis_link"/>
      <geom pos="0.0762025 2.19914e-05 -0.0884315" quat="1 0 0 0" type="mesh" rgba="0.7 0.7 0.7 1" mesh="imu_in_pelvis_link"/>
      <body name="hips_sphere" pos="0.0325 0.0 -0.0902351">
        <geom type="sphere" size="0.035" contype="0" conaffinity="0" group="1" density="0" rgba="0.6 0.6 0.6 0.0"/>
      </body>
      <body name="left_hip_pitch_link" pos="0.0325 0.0704672 -0.0902351" quat="0.976296 -0.21644 0 0">
        <inertial pos="-0.003907 0.0415 -0.043716" quat="0.977607 0.186708 0.0209888 0.0947863" mass="0.935482" diaginertia="0.00105051 0.000997373 0.000565117"/>
        <joint name="left_hip_pitch_joint" pos="0 0 0" axis="0 1 0" range="-2.93215 2.54818" actuatorfrcrange="-60 60"/>
        <geom type="mesh" contype="0" conaffinity="0" group="1" density="0" rgba="0.7 0.7 0.7 1" mesh="left_hip_pitch_link"/>
        <geom type="mesh" rgba="0.2 0.2 0.2 1" mesh="left_hip_pitch_link"/>
        <body name="left_hip_roll_link" pos="0.0248 0.045 -0.053" quat="0.976296 0.21644 0 0">
          <inertial pos="-0.008002 -0.00206 -0.032798" quat="0.917982 -0.152984 0.363871 0.0387668" mass="0.207609" diaginertia="0.000298715 0.000236156 0.000181129"/>
          <joint name="left_hip_roll_joint" pos="0 0 0" axis="1 0 0" range="-1.0472 1.74533" actuatorfrcrange="-60 60"/>
          <geom type="mesh" contype="0" conaffinity="0" group="1" density="0" rgba="0.7 0.7 0.7 1" mesh="left_hip_roll_link"/>
          <geom type="mesh" rgba="0.7 0.7 0.7 1" mesh="left_hip_roll_link"/>
          <body name="left_hip_yaw_link" pos="-0.0194507 -0.0006 -0.0618">
            <inertial pos="-0.010059 -0.004848 -0.093609" quat="0.648721 0.0354742 0.0856084 0.755364" mass="1.73967" diaginertia="0.0083895 0.00828665 0.00127385"/>
            <joint name="left_hip_yaw_joint" pos="0 0 0" axis="0 0 1" range="-2.7402 2.7402" actuatorfrcrange="-60 60"/>
            <geom type="mesh" contype="0" conaffinity="0" group="1" density="0" rgba="0.7 0.7 0.7 1" mesh="left_hip_yaw_link"/>
            <geom type="mesh" rgba="0.7 0.7 0.7 1" mesh="left_hip_yaw_link"/>
            <body name="left_knee_link" pos="-0.02315 0.01866 -0.159301">
              <inertial pos="-0.00945956 -0.0124217 -0.130949" quat="0.989411 -0.108674 0.0123777 -0.0954103" mass="2.37477" diaginertia="0.0159882 0.0147186 0.00341321"/>
              <joint name="left_knee_joint" pos="0 0 0" axis="0 1 0" range="-0.174533 2.42601" actuatorfrcrange="-60 60"/>
              <geom type="mesh" contype="0" conaffinity="0" group="1" density="0" rgba="0.7 0.7 0.7 1" mesh="left_knee_link"/>
              <geom type="mesh" rgba="0.7 0.7 0.7 1" mesh="left_knee_collision"/>
              <geom pos="0.0137908 -0.0205811 -0.0965262" quat="0.999002 0 0.0446656 0" type="mesh" contype="0" conaffinity="0" group="1" density="0" rgba="1 0 0 1" mesh="left_ankle_A_link"/>
              <geom pos="0.0137908 -0.0205811 -0.0965262" quat="0.999002 0 0.0446656 0" type="mesh" rgba="1 0 0 1" mesh="left_ankle_A_link"/>
              <geom pos="0.0263779 -0.00458488 -0.101716" quat="0.999002 0 0.0446656 0" type="mesh" contype="0" conaffinity="0" group="1" density="0" rgba="1 0 0 1" mesh="left_ankle_A_rod_link"/>
              <geom pos="0.00785625 -0.0205811 -0.162761" quat="0.999002 0 0.0446656 0" type="mesh" contype="0" conaffinity="0" group="1" density="0" rgba="0 0 1 1" mesh="left_ankle_B_link"/>
              <geom pos="0.00785625 -0.0205811 -0.162761" quat="0.999002 0 0.0446656 0" type="mesh" rgba="0 0 1 1" mesh="left_ankle_B_link"/>
              <geom pos="0.0204422 -0.0365743 -0.167963" quat="0.999002 0 0.0446656 0" type="mesh" contype="0" conaffinity="0" group="1" density="0" rgba="0 0 1 1" mesh="left_ankle_B_rod_link"/>
              <body name="left_ankle_pitch_link" pos="-0.0168139 -0.0205811 -0.309175">
                <inertial pos="-0.000104 0 -0.00772" quat="0.707107 0 0 0.707107" mass="0.071231" diaginertia="1.2e-05 7e-06 7e-06"/>
                <joint name="left_ankle_pitch_joint" pos="0 0 0" axis="0 1 0" range="-0.87266 0.57596" actuatorfrcrange="-50 50"/>
                <geom type="mesh" contype="0" conaffinity="0" group="1" density="0" rgba="0.7 0.7 0.7 1" mesh="left_ankle_pitch_link"/>
                <body name="left_ankle_roll_link">
                  <inertial pos="0.0296647 0 -0.0326975" quat="0 0.737468 0 0.675382" mass="0.481688" diaginertia="0.00126935 0.00121244 0.000230475"/>
                  <joint name="left_ankle_roll_joint" pos="0 0 0" axis="1 0 0" range="-0.2618 0.2618" actuatorfrcrange="-50 50"/>
                  <geom type="mesh" contype="0" conaffinity="0" group="1" density="0" rgba="0.4 0.4 0.4 1" mesh="left_ankle_roll_link"/>
                  <geom type="mesh" rgba="0.2 0.2 0.2 1" mesh="left_ankle_roll_link"/>
                  <geom pos="0.021 0.014 -0.0094" quat="1 0 0 0" type="mesh" contype="0" conaffinity="0" group="1" density="0" rgba="1 0 0 1" mesh="left_ankle_constraint_A_link"/>
                  <geom pos="0.021 0.014 -0.0094" quat="1 0 0 0" type="mesh" rgba="1 0 0 1" mesh="left_ankle_constraint_A_link"/>
                  <geom pos="0.021 -0.014 -0.0094" quat="1 0 0 0" type="mesh" contype="0" conaffinity="0" group="1" density="0" rgba="0 0 1 1" mesh="left_ankle_constraint_B_link"/>
                  <geom pos="0.021 -0.014 -0.0094" quat="1 0 0 0" type="mesh" rgba="0 0 1 1" mesh="left_ankle_constraint_B_link"/>
                  <body name="left_foot_end_link" pos="-0.04 0 -0.04">
                    <geom type="sphere" size="0.01" contype="0" conaffinity="0" group="1" density="0" rgba="1 0 0 0"/>
                  </body>
                  <body name="left_toe_link" pos="0.12 0 -0.04">
                    <geom type="sphere" size="0.01" contype="0" conaffinity="0" group="1" density="0" rgba="1 0 0 0"/>
                  </body>
                </body>
              </body>
            </body>
          </body>
        </body>
      </body>
      <body name="right_hip_pitch_link" pos="0.0325 -0.0704672 -0.0902351" quat="0.976296 0.21644 0 0">
        <inertial pos="-0.003907 -0.0415 -0.043716" quat="0.977607 -0.186708 0.0209888 -0.0947863" mass="0.935482" diaginertia="0.00105051 0.000997373 0.000565117"/>
        <joint name="right_hip_pitch_joint" pos="0 0 0" axis="0 1 0" range="-2.93215 2.54818" actuatorfrcrange="-60 60"/>
        <geom type="mesh" contype="0" conaffinity="0" group="1" density="0" rgba="0.2 0.2 0.2 1" mesh="right_hip_pitch_link"/>
        <geom type="mesh" rgba="0.2 0.2 0.2 1" mesh="right_hip_pitch_link"/>
        <body name="right_hip_roll_link" pos="0.0248 -0.045 -0.053" quat="0.976296 -0.21644 0 0">
          <inertial pos="-0.008002 0.00206 -0.032798" quat="0.917982 0.152984 0.363871 -0.0387668" mass="0.207609" diaginertia="0.000298715 0.000236156 0.000181129"/>
          <joint name="right_hip_roll_joint" pos="0 0 0" axis="1 0 0" range="-1.74533 1.0472" actuatorfrcrange="-60 60"/>
          <geom type="mesh" contype="0" conaffinity="0" group="1" density="0" rgba="0.7 0.7 0.7 1" mesh="right_hip_roll_link"/>
          <geom type="mesh" rgba="0.7 0.7 0.7 1" mesh="right_hip_roll_link"/>
          <body name="right_hip_yaw_link" pos="-0.0194507 0.0006 -0.0618">
            <inertial pos="-0.010059 0.004848 -0.093609" quat="0.755364 0.0856084 0.0354742 0.648721" mass="1.73967" diaginertia="0.0083895 0.00828665 0.00127385"/>
            <joint name="right_hip_yaw_joint" pos="0 0 0" axis="0 0 1" range="-2.7402 2.7402" actuatorfrcrange="-60 60"/>
            <geom type="mesh" contype="0" conaffinity="0" group="1" density="0" rgba="0.7 0.7 0.7 1" mesh="right_hip_yaw_link"/>
            <geom type="mesh" rgba="0.7 0.7 0.7 1" mesh="right_hip_yaw_link"/>
            <body name="right_knee_link" pos="-0.02315 -0.01866 -0.159301">
              <inertial pos="-0.00945956 0.0223594 -0.13014" quat="0.996238 -0.0295531 0.0208115 -0.0787615" mass="2.37477" diaginertia="0.0157119 0.014763 0.00313242"/>
              <joint name="right_knee_joint" pos="0 0 0" axis="0 1 0" range="-0.17453 2.42601" actuatorfrcrange="-60 60"/>
              <geom type="mesh" contype="0" conaffinity="0" group="1" density="0" rgba="0.7 0.7 0.7 1" mesh="right_knee_link"/>
              <geom type="mesh" rgba="0.7 0.7 0.7 1" mesh="right_knee_collision"/>
              <geom pos="0.0137908 0.0205811 -0.0965262" quat="0.999002 0 0.0446656 0" type="mesh" contype="0" conaffinity="0" group="1" density="0" rgba="1 0 0 1" mesh="right_ankle_A_link"/>
              <geom pos="0.0137908 0.0205811 -0.0965262" quat="0.999002 0 0.0446656 0" type="mesh" rgba="1 0 0 1" mesh="right_ankle_A_link"/>
              <geom pos="0.0263779 0.00458488 -0.101716" quat="0.999002 0 0.0446656 0" type="mesh" contype="0" conaffinity="0" group="1" density="0" rgba="1 0 0 1" mesh="right_ankle_A_rod_link"/>
              <geom pos="0.00785625 0.0205811 -0.162761" quat="0.999002 0 0.0446656 0" type="mesh" contype="0" conaffinity="0" group="1" density="0" rgba="0 0 1 1" mesh="right_ankle_B_link"/>
              <geom pos="0.00785625 0.0205811 -0.162761" quat="0.999002 0 0.0446656 0" type="mesh" rgba="0 0 1 1" mesh="right_ankle_B_link"/>
              <geom pos="0.0204422 0.0365743 -0.167963" quat="0.999002 0 0.0446656 0" type="mesh" contype="0" conaffinity="0" group="1" density="0" rgba="0 0 1 1" mesh="right_ankle_B_rod_link"/>
              <body name="right_ankle_pitch_link" pos="-0.0168139 0.0205811 -0.309175">
                <inertial pos="-0.000104 0 -0.00772" quat="0.707107 0 0 0.707107" mass="0.071231" diaginertia="1.2e-05 7e-06 7e-06"/>
                <joint name="right_ankle_pitch_joint" pos="0 0 0" axis="0 1 0" range="-0.87266 0.57596" actuatorfrcrange="-50 50"/>
                <geom type="mesh" contype="0" conaffinity="0" group="1" density="0" rgba="0.7 0.7 0.7 1" mesh="right_ankle_pitch_link"/>
                <body name="right_ankle_roll_link">
                  <inertial pos="0.0296647 0 -0.0326975" quat="0 0.737468 0 0.675382" mass="0.481688" diaginertia="0.00126935 0.00121244 0.000230475"/>
                  <joint name="right_ankle_roll_joint" pos="0 0 0" axis="1 0 0" range="-0.261799 0.261799" actuatorfrcrange="-50 50"/>
                  <geom type="mesh" contype="0" conaffinity="0" group="1" density="0" rgba="0.4 0.4 0.4 1" mesh="right_ankle_roll_link"/>
                  <geom type="mesh" rgba="0.2 0.2 0.2 1" mesh="right_ankle_roll_link"/>
                  <geom pos="0.021 -0.014 -0.0094" quat="1 0 0 0" type="mesh" contype="0" conaffinity="0" group="1" density="0" rgba="1 0 0 1" mesh="right_ankle_constraint_A_link"/>
                  <geom pos="0.021 -0.014 -0.0094" quat="1 0 0 0" type="mesh" rgba="1 0 0 1" mesh="right_ankle_constraint_A_link"/>
                  <geom pos="0.021 0.014 -0.0094" quat="1 0 0 0" type="mesh" contype="0" conaffinity="0" group="1" density="0" rgba="0 0 1 1" mesh="right_ankle_constraint_B_link"/>
                  <geom pos="0.021 0.014 -0.0094" quat="1 0 0 0" type="mesh" rgba="0 0 1 1" mesh="right_ankle_constraint_B_link"/>
                  <body name="right_foot_end_link" pos="-0.04 0 -0.04">
                    <geom type="sphere" size="0.01" contype="0" conaffinity="0" group="1" density="0" rgba="1 0 0 0"/>
                  </body>
                  <body name="right_toe_link" pos="0.12 0 -0.04">
                    <geom type="sphere" size="0.01" contype="0" conaffinity="0" group="1" density="0" rgba="1 0 0 0"/>
                  </body>
                </body>
              </body>
            </body>
          </body>
        </body>
      </body>
      <body name="waist_roll_link">
        <inertial pos="0.030601 0 0.004788" quat="0.999992 0 -0.00390592 0" mass="0.920736" diaginertia="0.000806008 0.000734 0.000677992"/>
        <joint name="waist_roll_joint" pos="0 0 0" axis="1 0 0" range="-0.5236 0.5236" actuatorfrcrange="-60 60"/>
        <geom pos="0.0325 0 0.049" type="mesh" contype="0" conaffinity="0" group="1" density="0" rgba="0.2 0.2 0.2 1" mesh="waist_roll_link"/>
        <geom pos="0.0325 0 0.049" type="mesh" rgba="0.2 0.2 0.2 1" mesh="waist_roll_link"/>
        <body name="waist_yaw_link" pos="0.0325 0 0.049">
          <inertial pos="-0.000648 -5.2e-05 0.144497" quat="0.999887 -0.0030653 -0.0143494 -0.00317387" mass="6.0242" diaginertia="0.0609794 0.0506456 0.024571"/>
          <joint name="waist_yaw_joint" pos="0 0 0" axis="0 0 1" range="-2.618 2.618" actuatorfrcrange="-60 60"/>
          <geom type="mesh" contype="0" conaffinity="0" group="1" density="0" rgba="0.7 0.7 0.7 1" mesh="waist_yaw_link"/>
          <geom type="mesh" rgba="0.4 0.4 0.4 1" mesh="waist_yaw_link"/>
          <body name="left_shoulder_pitch_link" pos="0 0.085688 0.19749" quat="0.99144 0.130561 0 0">
            <inertial pos="0.00294386 0.0447687 -0.0228687" quat="0.933514 0.315801 -0.107611 0.131308" mass="0.83795" diaginertia="0.000664554 0.000644431 0.000530845"/>
            <joint name="left_shoulder_pitch_joint" pos="0 0 0" axis="0 1 0" range="-3.1416 2.0944" actuatorfrcrange="-60 60"/>
            <geom type="mesh" contype="0" conaffinity="0" group="1" density="0" rgba="0.7 0.7 0.7 1" mesh="left_shoulder_pitch_link"/>
            <geom type="mesh" rgba="0.7 0.7 0.7 1" mesh="left_shoulder_pitch_link"/>
            <body name="left_shoulder_sphere" pos="0.0 0.047132 -0.025693">
              <geom type="sphere" size="0.035" contype="0" conaffinity="0" group="1" density="0" rgba="0.6 0.6 0.6 0.35"/>
            </body>
            <body name="left_shoulder_roll_link" pos="0.03445 0.047132 -0.025693" quat="0.99144 -0.130561 0 0">
              <inertial pos="-0.037828 0.003967 -0.066496" quat="0.704928 -0.0676661 -0.0976966 0.699252" mass="0.740212" diaginertia="0.00108994 0.000995148 0.000547915"/>
              <joint name="left_shoulder_roll_joint" pos="0 0 0" axis="1 0 0" range="-0.22689 2.4784" actuatorfrcrange="-60 60"/>
              <geom type="mesh" contype="0" conaffinity="0" group="1" density="0" rgba="0.7 0.7 0.7 1" mesh="left_shoulder_roll_link"/>
              <geom type="mesh" rgba="0.7 0.7 0.7 1" mesh="left_shoulder_roll_link"/>
              <body name="left_shoulder_yaw_link" pos="-0.03445 0.0043 -0.10835">
                <inertial pos="0.013143 -0.004355 -0.072948" quat="0.944453 -0.083861 -0.114993 0.29623" mass="0.738441" diaginertia="0.000862551 0.000851784 0.000435665"/>
                <joint name="left_shoulder_yaw_joint" pos="0 0 0" axis="0 0 1" range="-1.9199 1.9199" actuatorfrcrange="-33 33"/>
                <geom type="mesh" contype="0" conaffinity="0" group="1" density="0" rgba="0.7 0.7 0.7 1" mesh="left_shoulder_yaw_link"/>
                <geom type="mesh" rgba="0.7 0.7 0.7 1" mesh="left_shoulder_yaw_link"/>
                <body name="left_elbow_link" pos="0.016191 0.026461 -0.082858">
                  <inertial pos="0.072371 -0.024612 -0.011566" quat="0.590432 0.585258 0.4407 0.338595" mass="0.759419" diaginertia="0.000969031 0.000938046 0.000470923"/>
                  <joint name="left_elbow_joint" pos="0 0 0" axis="0 1 0" range="-0.97564 2.1852" actuatorfrcrange="-33 33"/>
                  <geom type="mesh" contype="0" conaffinity="0" group="1" density="0" rgba="0.7 0.7 0.7 1" mesh="left_elbow_link"/>
                  <geom type="mesh" rgba="0.7 0.7 0.7 1" mesh="left_elbow_link"/>
                  <body name="left_wrist_roll_link" pos="0.11218 -0.03002 -0.011702">
                    <inertial pos="0.068045 -0.001688 0.001392" quat="0.442664 0.566917 0.411512 0.559742" mass="0.324767" diaginertia="0.000717953 0.000704181 0.000156865"/>
                    <joint name="left_wrist_roll_joint" pos="0 0 0" axis="1 0 0" range="-1.9199 1.9199" actuatorfrcrange="-33 33"/>
                    <geom type="mesh" contype="0" conaffinity="0" group="1" density="0" rgba="0.4 0.4 0.4 1" mesh="left_wrist_roll_link"/>
                    <geom type="mesh" rgba="0.4 0.4 0.4 1" mesh="left_wrist_roll_link"/>
                    <body name="left_hand" pos="0.07 0.0 0.0">
                      <geom type="sphere" size="0.035" contype="0" conaffinity="0" group="1" density="0" rgba="0.6 0.6 0.6 0.0"/>
                    </body>
                  </body>
                </body>
              </body>
            </body>
          </body>
          <body name="right_shoulder_pitch_link" pos="0 -0.085688 0.19749" quat="0.99144 -0.130561 0 0">
            <inertial pos="0.00294386 -0.0447687 -0.0228687" quat="0.933514 -0.315801 -0.107611 -0.131308" mass="0.83795" diaginertia="0.000664554 0.000644431 0.000530845"/>
            <joint name="right_shoulder_pitch_joint" pos="0 0 0" axis="0 1 0" range="-3.1416 2.0944" actuatorfrcrange="-60 60"/>
            <geom type="mesh" contype="0" conaffinity="0" group="1" density="0" rgba="0.7 0.7 0.7 1" mesh="right_shoulder_pitch_link"/>
            <geom type="mesh" rgba="0.7 0.7 0.7 1" mesh="right_shoulder_pitch_link"/>
            <body name="right_shoulder_sphere" pos="0.0 -0.047132 -0.025693">
              <geom type="sphere" size="0.035" contype="0" conaffinity="0" group="1" density="0" rgba="0.6 0.6 0.6 0.35"/>
            </body>
            <body name="right_shoulder_roll_link" pos="0.03445 -0.047132 -0.025693" quat="0.99144 0.130561 0 0">
              <inertial pos="-0.037828 -0.003967 -0.066496" quat="0.699252 -0.0976966 -0.0676661 0.704928" mass="0.740212" diaginertia="0.00108994 0.000995148 0.000547915"/>
              <joint name="right_shoulder_roll_joint" pos="0 0 0" axis="1 0 0" range="-2.47849 0.2268" actuatorfrcrange="-60 60"/>
              <geom type="mesh" contype="0" conaffinity="0" group="1" density="0" rgba="0.7 0.7 0.7 1" mesh="right_shoulder_roll_link"/>
              <geom type="mesh" rgba="0.7 0.7 0.7 1" mesh="right_shoulder_roll_link"/>
              <body name="right_shoulder_yaw_link" pos="-0.03445 -0.0043 -0.10835">
                <inertial pos="0.013143 0.004355 -0.072948" quat="0.944453 0.083861 -0.114993 -0.29623" mass="0.738441" diaginertia="0.000862551 0.000851784 0.000435665"/>
                <joint name="right_shoulder_yaw_joint" pos="0 0 0" axis="0 0 1" range="-1.9199 1.9199" actuatorfrcrange="-33 33"/>
                <geom type="mesh" contype="0" conaffinity="0" group="1" density="0" rgba="0.7 0.7 0.7 1" mesh="right_shoulder_yaw_link"/>
                <geom type="mesh" rgba="0.7 0.7 0.7 1" mesh="right_shoulder_yaw_link"/>
                <body name="right_elbow_link" pos="0.016191 -0.026461 -0.082858">
                  <inertial pos="0.072371 0.024612 -0.011566" quat="0.338595 0.4407 0.585258 0.590432" mass="0.759419" diaginertia="0.000969031 0.000938046 0.000470923"/>
                  <joint name="right_elbow_joint" pos="0 0 0" axis="0 1 0" range="-0.97564 2.1852" actuatorfrcrange="-33 33"/>
                  <geom type="mesh" contype="0" conaffinity="0" group="1" density="0" rgba="0.7 0.7 0.7 1" mesh="right_elbow_link"/>
                  <geom type="mesh" rgba="0.7 0.7 0.7 1" mesh="right_elbow_link"/>
                  <body name="right_wrist_roll_link" pos="0.11218 0.03002 -0.011702">
                    <inertial pos="0.068045 0.001688 0.001392" quat="0.559742 0.411512 0.566917 0.442664" mass="0.324767" diaginertia="0.000717953 0.000704181 0.000156865"/>
                    <joint name="right_wrist_roll_joint" pos="0 0 0" axis="1 0 0" range="-1.9199 1.9199" actuatorfrcrange="-33 33"/>
                    <geom type="mesh" contype="0" conaffinity="0" group="1" density="0" rgba="0.4 0.4 0.4 1" mesh="right_wrist_roll_link"/>
                    <geom type="mesh" rgba="0.4 0.4 0.4 1" mesh="right_wrist_roll_link"/>
                    <body name="right_hand" pos="0.07 0.0 0.0">
                      <geom type="sphere" size="0.035" contype="0" conaffinity="0" group="1" density="0" rgba="0.6 0.6 0.6 0.0"/>
                    </body>
                  </body>
                </body>
              </body>
            </body>
          </body>
          <body name="neck_sphere" pos="0 0.0 0.19749">
              <geom type="sphere" size="0.035" contype="0" conaffinity="0" group="1" density="0" rgba="0.6 0.6 0.6 0.35"/>
          </body>
          <body name="head_pitch_link" pos="-0.006 0.03155 0.255">
            <inertial pos="-6.956e-05 -0.0307797 0.0805859" quat="0.999952 0.00642081 -0.00613861 -0.00401818" mass="0.503913" diaginertia="0.00096003 0.000913512 0.000453408"/>
            <joint name="head_pitch_joint" pos="0 0 0" axis="0 1 0" range="-0.62832 0.62832" actuatorfrcrange="-33 33"/>
            <geom type="mesh" contype="0" conaffinity="0" group="1" density="0" rgba="0.7 0.7 0.7 1" mesh="head_pitch_link"/>
            <geom type="mesh" rgba="0.7 0.7 0.7 1" mesh="head_pitch_link"/>
            <body name="head_yaw_link" pos="0.0010126 -0.03155 0.1165">
              <inertial pos="0.0221166 -4.725e-05 0.00199411" quat="0.00116008 0.901357 0.00238347 0.433068" mass="0.714322" diaginertia="0.00205103 0.00202452 0.00144527"/>
              <joint name="head_yaw_joint" pos="0 0 0" axis="0 0 1" range="-2.0071 2.0071" actuatorfrcrange="-33 33"/>
              <geom type="mesh" contype="0" conaffinity="0" group="1" density="0" rgba="0.7 0.7 0.7 1" mesh="head_yaw_link"/>
              <geom type="mesh" rgba="0.7 0.7 0.7 1" mesh="head_yaw_link"/>
            </body>
          </body>
        </body>
      </body>
    </body>
  </worldbody>

  <actuator>
    <motor name="left_hip_pitch_joint" joint="left_hip_pitch_joint"/>
    <motor name="left_hip_roll_joint" joint="left_hip_roll_joint"/>
    <motor name="left_hip_yaw_joint" joint="left_hip_yaw_joint"/>
    <motor name="left_knee_joint" joint="left_knee_joint"/>
    <motor name="left_ankle_pitch_joint" joint="left_ankle_pitch_joint"/>
    <motor name="left_ankle_roll_joint" joint="left_ankle_roll_joint"/>
    <motor name="right_hip_pitch_joint" joint="right_hip_pitch_joint"/>
    <motor name="right_hip_roll_joint" joint="right_hip_roll_joint"/>
    <motor name="right_hip_yaw_joint" joint="right_hip_yaw_joint"/>
    <motor name="right_knee_joint" joint="right_knee_joint"/>
    <motor name="right_ankle_pitch_joint" joint="right_ankle_pitch_joint"/>
    <motor name="right_ankle_roll_joint" joint="right_ankle_roll_joint"/>
    <motor name="waist_yaw_joint" joint="waist_yaw_joint"/>
    <motor name="waist_roll_joint" joint="waist_roll_joint"/>
    <motor name="left_shoulder_pitch_joint" joint="left_shoulder_pitch_joint"/>
    <motor name="left_shoulder_roll_joint" joint="left_shoulder_roll_joint"/>
    <motor name="left_shoulder_yaw_joint" joint="left_shoulder_yaw_joint"/>
    <motor name="left_elbow_joint" joint="left_elbow_joint"/>
    <motor name="left_wrist_roll_joint" joint="left_wrist_roll_joint"/>
    <motor name="right_shoulder_pitch_joint" joint="right_shoulder_pitch_joint"/>
    <motor name="right_shoulder_roll_joint" joint="right_shoulder_roll_joint"/>
    <motor name="right_shoulder_yaw_joint" joint="right_shoulder_yaw_joint"/>
    <motor name="right_elbow_joint" joint="right_elbow_joint"/>
    <motor name="right_wrist_roll_joint" joint="right_wrist_roll_joint"/>
  </actuator>

  <!-- <statistic center="1.0 0.7 1.0" extent="0.8"/>
  <visual>
    <headlight diffuse="0.6 0.6 0.6" ambient="0.1 0.1 0.1" specular="0.9 0.9 0.9"/>
    <rgba haze="0.15 0.25 0.35 1"/>
    <global azimuth="-140" elevation="-20"/>
  </visual>
  <asset>
    <texture type="skybox" builtin="flat" rgb1="0 0 0" rgb2="0 0 0" width="512" height="3072"/>
    <texture type="2d" name="groundplane" builtin="checker" mark="edge" rgb1="0.2 0.3 0.4" rgb2="0.1 0.2 0.3" markrgb="0.8 0.8 0.8" width="300" height="300"/>
    <material name="groundplane" texture="groundplane" texuniform="true" texrepeat="5 5" reflectance="0.2"/>
  </asset>
  <worldbody>
    <light pos="1 0 3.5" dir="0 0 -1" directional="true"/>
    <geom name="floor" size="0 0 0.05" type="plane" material="groundplane" friction="0.75 0.02 0.001"/>
  </worldbody> -->
</mujoco>
